Workbook

Sheet دليل الاستخدام
B1: دليل استخدام ملف تسيير النشاط والتنبؤ
B2: اقرأ هذه الصفحة أولاً قبل البدء
B4: 1. أدخل مشترياتك: افتح شيت «إدخال المشتريات» وأضف كل عملية شراء في صف جديد: التاريخ، اسم المنتج (اختره من القائمة المنسدلة)، الكمية، سعر الشراء للوحدة. عمود الإجمالي يُحسب تلقائياً.
B7: 2. أدخل مبيعاتك: بنفس الطريقة في شيت «إدخال المبيعات». يمكنك إدخال كل عملية بيع، أو تجميع مبيعات اليوم لكل منتج في صف واحد يومياً — كلما كان الإدخال أدق، كانت التقارير والتنبؤ أدق.
B10: 3. أضف منتجاً جديداً: أضفه أولاً في شيت «المنتجات» (الاسم فقط)، وسيظهر تلقائياً في القوائم المنسدلة وباقي التقارير.
B13: 4. لا تكتب في الشيتات الأخرى: شيت «لوحة القيادة» و«تقرير المنتجات» و«التنبؤ وإعادة الطلب» و«التقرير الشهري» محسوبة تلقائياً بالكامل — لا تُدخل فيها بيانات يدوياً.
B16: 5. لتغيير الفترة المعروضة: من شيت «لوحة القيادة»، غيّر خليتي «من تاريخ» و«إلى تاريخ» بالأعلى، وستتحدث كل التقارير المرتبطة بالفترة تلقائياً.
B19: 6. حدود إعادة الطلب وتاريخ البداية: في شيت «المنتجات»، حدد لكل منتج «حد إعادة الطلب» ليظهر تنبيه عند اقتراب النفاد. عمود «تاريخ بداية البيع الفعلي» يُستخدم في حساب التنبؤ بدقة (مُعبّأ مسبقاً للمنتجات الحالية) - لأي منتج جديد اتركه فارغاً وسيُحسب تلقائياً من أول عملية بيع تُدخلها له.
B22: 7. الخلايا الصفراء فقط قابلة للتعديل: أي خلية بخلفية صفراء فاتحة هي خلية إدخال يدوي. باقي الخلايا (البيضاء/الرمادية) تحتوي على معادلات، تجنّب الكتابة فوقها.
B26: ملاحظة: بيانات المشتريات المدرجة مسبقاً (18 عملية) وبيانات المبيعات (8 أسطر) هي أرقامك الفعلية من 2026-06-01 إلى 2026-07-28 كنقطة انطلاق — أضف ما بعدها كصفوف جديدة.

Sheet لوحة القيادة
B1: لوحة القيادة - ملخص الأداء
B2: غيّر الفترة أدناه لتحديث كل التقارير المرتبطة بها تلقائياً
B4: من تاريخ: | C4: 46023 | D4: إلى تاريخ: | E4: 47848
B6: إجمالي المبيعات (ضمن الفترة) | D6: ='تقرير المنتجات'!$G$35 -> 2574553.3 | E6: دج
B7: إجمالي المشتريات (ضمن الفترة) | D7: ='تقرير المنتجات'!$D$35 -> 3185390 | E7: دج
B8: الربح التقديري (ضمن الفترة) | D8: ='تقرير المنتجات'!$I$35 -> 351283.02 | E8: دج
B9: هامش الربح الإجمالي | D9: ='تقرير المنتجات'!$J$35 -> 0.13644426
B10: عدد الوحدات المباعة (ضمن الفترة) | D10: ='تقرير المنتجات'!$F$35 -> 5149 | E10: وحدة
B11: قيمة المخزون الحالي (بسعر الشراء) | D11: =SUMPRODUCT(IFERROR('تقرير المنتجات'!$K$5:$K$34*1,0),IFERROR('تقرير المنتجات'!$E$5:$E$34,0)) -> 170885 | E11: دج
B12: عدد المنتجات التي تحتاج إعادة طلب | D12: =COUNTIF('تقرير المنتجات'!$L$5:$L$34,"⚠ أعد الطلب") -> 3 | E12: منتج
B15: أفضل وأضعف منتج من حيث الربح (ضمن الفترة المحددة)
B16: الأعلى ربحاً: | C16: =INDEX('تقرير المنتجات'!$B$5:$B$34,MATCH(MAX('تقرير المنتجات'!$I$5:$I$34),'تقرير المنتجات'!$I$5:$I$34,0)) -> عصير جومانة 2ل
B17: الأضعف ربحاً: | C17: =INDEX('تقرير المنتجات'!$B$5:$B$34,MATCH(MIN('تقرير المنتجات'!$I$5:$I$34),'تقرير المنتجات'!$I$5:$I$34,0)) -> قازوز فرحة 33سل
B19: لعرض «كل البيانات» بدون فلترة، اترك من/إلى بالقيم الافتراضية أعلاه. لعرض شهر معين فقط، ضع تاريخ أول وآخر يوم في ذلك الشهر.

Sheet المنتجات
B1: قائمة المنتجات
B2: أضف منتجاً جديداً هنا أولاً قبل استخدامه في المشتريات/المبيعات
B4: # | C4: اسم المنتج | D4: تاريخ بداية البيع الفعلي (اختياري) | E4: حد إعادة الطلب (وحدة) | F4: ملاحظات
B5: 1 | C5: عصير جومانة 2ل | D5: 46198 | E5: 50
B6: 2 | C6: عصير كين دور 1.25ل | D6: 46198 | E6: 50
B7: 3 | C7: عصير مدى 33سل | D7: 46198 | E7: 50
B8: 4 | C8: عصير اكسترا 2ل | D8: 46198 | E8: 50
B9: 5 | C9: عصير مدى 1.5ل | D9: 46198 | E9: 50
B10: 6 | C10: جيليكس 2ل | D10: 46214 | E10: 50
B11: 7 | C11: جي اروى 2ل | D11: 46216 | E11: 50
B12: 8 | C12: اورنجينا 2 لتر | D12: 46216 | E12: 50
B13: 9 | C13: قازوز فرحة 33سل | D13: 46234 | E13: 50
B14: 10
B15: 11
B16: 12
B17: 13
B18: 14
B19: 15
B20: 16
B21: 17
B22: 18
B23: 19
B24: 20
B25: 21
... B34: 30

Sheet إدخال المشتريات
B1: إدخال المشتريات
B2: أضف كل عملية شراء في صف جديد — الخلايا الصفراء فقط تُملأ يدوياً
B4: التاريخ | C4: اسم المنتج | D4: الكمية | E4: سعر الشراء / وحدة | F4: الإجمالي (دج) | G4: المورد (اختياري)
B5: 46198 | C5: عصير مدى 1.5ل | D5: 240 | E5: 500 | F5: =IF(OR(D5="",E5=""),"",D5*E5) -> 120000
B6: 46198 | C6: عصير مدى 33سل | D6: 400 | E6: 320 | F6: =IF(OR(D6="",E6=""),"",D6*E6) -> 128000
B7: 46198 | C7: عصير اكسترا 2ل | D7: 320 | E7: 500 | F7: =IF(OR(D7="",E7=""),"",D7*E7) -> 160000
B8: 46198 | C8: عصير كين دور 1.25ل | D8: 750 | E8: 305 | F8: =IF(OR(D8="",E8=""),"",D8*E8) -> 228750
B9: 46198 | C9: عصير جومانة 2ل | D9: 640 | E9: 370 | F9: =IF(OR(D9="",E9=""),"",D9*E9) -> 236800
B10: 46214 | C10: جيليكس 2ل | D10: 160 | E10: 490 | F10: =IF(OR(D10="",E10=""),"",D10*E10) -> 78400
B11: 46216 | C11: جي اروى 2ل | D11: 80 | E11: 715 | F11: =IF(OR(D11="",E11=""),"",D11*E11) -> 57200
B12: 46216 | C12: اورنجينا 2 لتر | D12: 80 | E12: 715 | F12: =IF(OR(D12="",E12=""),"",D12*E12) -> 57200
B13: 46218 | C13: جيليكس 2ل | D13: 160 | E13: 485 | F13: =IF(OR(D13="",E13=""),"",D13*E13) -> 77600
B14: 46226 | C14: جي اروى 2ل | D14: 240 | E14: 715 | F14: =IF(OR(D14="",E14=""),"",D14*E14) -> 171600
B15: 46226 | C15: اورنجينا 2 لتر | D15: 160 | E15: 715 | F15: =IF(OR(D15="",E15=""),"",D15*E15) -> 114400
B16: 46226 | C16: جيليكس 2ل | D16: 240 | E16: 485 | F16: =IF(OR(D16="",E16=""),"",D16*E16) -> 116400
... B26: 46236 | C26: اورنجينا 2 لتر | D26: 240 | E26: 715 | F26: =IF(OR(D26="",E26=""),"",D26*E26) -> 171600
B27: 46234 | C27: قازوز فرحة 33سل | D27: 35 | E27: 220 | F27: =IF(OR(D27="",E27=""),"",D27*E27) -> 7700 | G27: تقديري - غير مذكور في تقرير المشتريات
B28: 46235 | C28: عصير مدى 1.5ل | D28: 80 | E28: 500 | F28: =IF(OR(D28="",E28=""),"",D28*E28) -> 40000
B29: 46235 | C29: عصير مدى 33سل | D29: 600 | E29: 320 | F29: =IF(OR(D29="",E29=""),"",D29*E29) -> 192000
B30: 46235 | C30: عصير جومانة 2ل | D30: 640 | E30: 370 | F30: =IF(OR(D30="",E30=""),"",D30*E30) -> 236800
F31: =IF(OR(D31="",E31=""),"",D31*E31)
F32: =IF(OR(D32="",E32=""),"",D32*E32)
F33: =IF(OR(D33="",E33=""),"",D33*E33)
F34: =IF(OR(D34="",E34=""),"",D34*E34)
F35: =IF(OR(D35="",E35=""),"",D35*E35)
F36: =IF(OR(D36="",E36=""),"",D36*E36)
F37: =IF(OR(D37="",E37=""),"",D37*E37)
F38: =IF(OR(D38="",E38=""),"",D38*E38)
F39: =IF(OR(D39="",E39=""),"",D39*E39)
F40: =IF(OR(D40="",E40=""),"",D40*E40)
F41: =IF(OR(D41="",E41=""),"",D41*E41)
F42: =IF(OR(D42="",E42=""),"",D42*E42)
... F304: =IF(OR(D304="",E304=""),"",D304*E304)

Sheet إدخال المبيعات
B1: إدخال المبيعات
B2: أضف كل عملية بيع (أو مبيعات اليوم لكل منتج) في صف جديد
B4: التاريخ | C4: اسم المنتج | D4: الكمية | E4: سعر البيع / وحدة | F4: الإجمالي (دج) | G4: العميل (اختياري) | H4: ملاحظات
B5: 46231 | C5: عصير جومانة 2ل | D5: 989 | E5: 447.57 | F5: =IF(OR(D5="",E5=""),"",D5*E5) -> 442646.73 | H5: دفعة تراكمية (نقطة انطلاق/تحديث) من تقارير POS - وليست عملية بيع واحدة فعلية
B6: 46231 | C6: جيليكس 2ل | D6: 743 | E6: 520 | F6: =IF(OR(D6="",E6=""),"",D6*E6) -> 386360 | H6: دفعة تراكمية (نقطة انطلاق/تحديث) من تقارير POS - وليست عملية بيع واحدة فعلية
B7: 46231 | C7: عصير كين دور 1.25ل | D7: 890 | E7: 376.85 | F7: =IF(OR(D7="",E7=""),"",D7*E7) -> 335396.5 | H7: دفعة تراكمية (نقطة انطلاق/تحديث) من تقارير POS - وليست عملية بيع واحدة فعلية
B8: 46231 | C8: عصير مدى 33سل | D8: 599 | E8: 396.16 | F8: =IF(OR(D8="",E8=""),"",D8*E8) -> 237299.84 | H8: دفعة تراكمية (نقطة انطلاق/تحديث) من تقارير POS - وليست عملية بيع واحدة فعلية
B9: 46231 | C9: جي اروى 2ل | D9: 290 | E9: 760 | F9: =IF(OR(D9="",E9=""),"",D9*E9) -> 220400 | H9: دفعة تراكمية (نقطة انطلاق/تحديث) من تقارير POS - وليست عملية بيع واحدة فعلية
B10: 46231 | C10: عصير اكسترا 2ل | D10: 316 | E10: 598.04 | F10: =IF(OR(D10="",E10=""),"",D10*E10) -> 188980.64 | H10: دفعة تراكمية (نقطة انطلاق/تحديث) من تقارير POS - وليست عملية بيع واحدة فعلية
B11: 46231 | C11: عصير مدى 1.5ل | D11: 292 | E11: 599.21 | F11: =IF(OR(D11="",E11=""),"",D11*E11) -> 174969.32 | H11: دفعة تراكمية (نقطة انطلاق/تحديث) من تقارير POS - وليست عملية بيع واحدة فعلية
B12: 46231 | C12: اورنجينا 2 لتر | D12: 191 | E12: 760 | F12: =IF(OR(D12="",E12=""),"",D12*E12) -> 145160 | H12: دفعة تراكمية (نقطة انطلاق/تحديث) من تقارير POS - وليست عملية بيع واحدة فعلية
B13: 46236 | C13: عصير جومانة 2ل | D13: 213 | E13: 461.27 | F13: =IF(OR(D13="",E13=""),"",D13*E13) -> 98250.51 | H13: دفعة تراكمية (نقطة انطلاق/تحديث) من تقارير POS - وليست عملية بيع واحدة فعلية
B14: 46236 | C14: عصير كين دور 1.25ل | D14: 67 | E14: 421.79 | F14: =IF(OR(D14="",E14=""),"",D14*E14) -> 28259.93 | H14: دفعة تراكمية (نقطة انطلاق/تحديث) من تقارير POS - وليست عملية بيع واحدة فعلية
B15: 46236 | C15: عصير مدى 33سل | D15: 54 | E15: 442.59 | F15: =IF(OR(D15="",E15=""),"",D15*E15) -> 23899.86 | H15: دفعة تراكمية (نقطة انطلاق/تحديث) من تقارير POS - وليست عملية بيع واحدة فعلية
B16: 46236 | C16: عصير مدى 1.5ل | D16: 25 | E16: 609.2 | F16: =IF(OR(D16="",E16=""),"",D16*E16) -> 15230 | H16: دفعة تراكمية (نقطة انطلاق/تحديث) من تقارير POS - وليست عملية بيع واحدة فعلية
... B20: 46236 | C20: قازوز فرحة 33سل | D20: 35 | E20: 260 | F20: =IF(OR(D20="",E20=""),"",D20*E20) -> 9100 | H20: دفعة تراكمية (نقطة انطلاق/تحديث) من تقارير POS - وليست عملية بيع واحدة فعلية
F21: =IF(OR(D21="",E21=""),"",D21*E21)
F22: =IF(OR(D22="",E22=""),"",D22*E22)
F23: =IF(OR(D23="",E23=""),"",D23*E23)
F24: =IF(OR(D24="",E24=""),"",D24*E24)
F25: =IF(OR(D25="",E25=""),"",D25*E25)
F26: =IF(OR(D26="",E26=""),"",D26*E26)
F27: =IF(OR(D27="",E27=""),"",D27*E27)
F28: =IF(OR(D28="",E28=""),"",D28*E28)
F29: =IF(OR(D29="",E29=""),"",D29*E29)
F30: =IF(OR(D30="",E30=""),"",D30*E30)
F31: =IF(OR(D31="",E31=""),"",D31*E31)
F32: =IF(OR(D32="",E32=""),"",D32*E32)
... F304: =IF(OR(D304="",E304=""),"",D304*E304)

Sheet تقرير المنتجات
B1: تقرير الربحية والمخزون حسب المنتج
B2: الفترة تُحدَّد من شيت «لوحة القيادة» (خلايا من/إلى تاريخ)
B4: المنتج | C4: كمية مشتراة (ضمن الفترة) | D4: قيمة المشتريات (ضمن الفترة) | E4: متوسط سعر الشراء (كل الفترات) | F4: كمية مباعة (ضمن الفترة) | G4: قيمة المبيعات (ضمن الفترة) | H4: تكلفة البضاعة المباعة (تقديرية) | I4: الربح التقديري | J4: هامش الربح % | K4: المخزون الحالي (كل الفترات) | L4: حالة المخزون | M4: الترتيب حسب الربح
B5: =المنتجات!$C$5 -> عصير جومانة 2ل | C5: =IF(المنتجات!$C$5="","",SUMIFS('إدخال المشتريات'!$D:$D,'إدخال المشتريات'!$C:$C,المنتجات!$C$5,'إدخال المشتريات'!$B:$B,">="&'لوحة القيادة'!$C$4,'إدخال المشتريات'!$B:$B,"<="&'لوحة القيادة'!$E$4)) -> 1840 | D5: =IF(المنتجات!$C$5="","",SUMIFS('إدخال المشتريات'!$F:$F,'إدخال المشتريات'!$C:$C,المنتجات!$C$5,'إدخال المشتريات'!$B:$B,">="&'لوحة القيادة'!$C$4,'إدخال المشتريات'!$B:$B,"<="&'لوحة القيادة'!$E$4)) -> 680800 | E5: =IF(المنتجات!$C$5="","",IFERROR(SUMIFS('إدخال المشتريات'!$F:$F,'إدخال المشتريات'!$C:$C,المنتجات!$C$5)/SUMIFS('إدخال المشتريات'!$D:$D,'إدخال المشتريات'!$C:$C,المنتجات!$C$5),0)) -> 370 | F5: =IF(المنتجات!$C$5="","",SUMIFS('إدخال المبيعات'!$D:$D,'إدخال المبيعات'!$C:$C,المنتجات!$C$5,'إدخال المبيعات'!$B:$B,">="&'لوحة القيادة'!$C$4,'إدخال المبيعات'!$B:$B,"<="&'لوحة القيادة'!$E$4)) -> 1202 | G5: =IF(المنتجات!$C$5="","",SUMIFS('إدخال المبيعات'!$F:$F,'إدخال المبيعات'!$C:$C,المنتجات!$C$5,'إدخال المبيعات'!$B:$B,">="&'لوحة القيادة'!$C$4,'إدخال المبيعات'!$B:$B,"<="&'لوحة القيادة'!$E$4)) -> 540897.24 | H5: =IF(المنتجات!$C$5="","",E5*F5) -> 444740 | I5: =IF(المنتجات!$C$5="","",G5-H5) -> 96157.24 | J5: =IF(OR(المنتجات!$C$5="",G5=0),"",I5/G5) -> 0.17777358 | K5: =IF(المنتجات!$C$5="","",SUMIFS('إدخال المشتريات'!$D:$D,'إدخال المشتريات'!$C:$C,المنتجات!$C$5)-SUMIFS('إدخال المبيعات'!$D:$D,'إدخال المبيعات'!$C:$C,المنتجات!$C$5)) -> 638 | L5: =IF(المنتجات!$C$5="","",IF(K5<=المنتجات!$E$5,"⚠ أعد الطلب","جيد")) -> جيد | M5: =IF(OR(المنتجات!$C$5="",I5=""),"",RANK(I5,$I$5:$I$34)) -> 1
B6: =المنتجات!$C$6 -> عصير كين دور 1.25ل | C6: =IF(المنتجات!$C$6="","",SUMIFS('إدخال المشتريات'!$D:$D,'إدخال المشتريات'!$C:$C,المنتجات!$C$6,'إدخال المشتريات'!$B:$B,">="&'لوحة القيادة'!$C$4,'إدخال المشتريات'!$B:$B,"<="&'لوحة القيادة'!$E$4)) -> 938 | D6: =IF(المنتجات!$C$6="","",SUMIFS('إدخال المشتريات'!$F:$F,'إدخال المشتريات'!$C:$C,المنتجات!$C$6,'إدخال المشتريات'!$B:$B,">="&'لوحة القيادة'!$C$4,'إدخال المشتريات'!$B:$B,"<="&'لوحة القيادة'!$E$4)) -> 286090 | E6: =IF(المنتجات!$C$6="","",IFERROR(SUMIFS('إدخال المشتريات'!$F:$F,'إدخال المشتريات'!$C:$C,المنتجات!$C$6)/SUMIFS('إدخال المشتريات'!$D:$D,'إدخال المشتريات'!$C:$C,المنتجات!$C$6),0)) -> 305 | F6: =IF(المنتجات!$C$6="","",SUMIFS('إدخال المبيعات'!$D:$D,'إدخال المبيعات'!$C:$C,المنتجات!$C$6,'إدخال المبيعات'!$B:$B,">="&'لوحة القيادة'!$C$4,'إدخال المبيعات'!$B:$B,"<="&'لوحة القيادة'!$E$4)) -> 957 | G6: =IF(المنتجات!$C$6="","",SUMIFS('إدخال المبيعات'!$F:$F,'إدخال المبيعات'!$C:$C,المنتجات!$C$6,'إدخال المبيعات'!$B:$B,">="&'لوحة القيادة'!$C$4,'إدخال المبيعات'!$B:$B,"<="&'لوحة القيادة'!$E$4)) -> 363656.43 | H6: =IF(المنتجات!$C$6="","",E6*F6) -> 291885 | I6: =IF(المنتجات!$C$6="","",G6-H6) -> 71771.43 | J6: =IF(OR(المنتجات!$C$6="",G6=0),"",I6/G6) -> 0.19736054 | K6: =IF(المنتجات!$C$6="","",SUMIFS('إدخال المشتريات'!$D:$D,'إدخال المشتريات'!$C:$C,المنتجات!$C$6)-SUMIFS('إدخال المبيعات'!$D:$D,'إدخال المبيعات'!$C:$C,المنتجات!$C$6)) -> -19 | L6: =IF(المنتجات!$C$6="","",IF(K6<=المنتجات!$E$6,"⚠ أعد الطلب","جيد")) -> ⚠ أعد الطلب | M6: =IF(OR(المنتجات!$C$6="",I6=""),"",RANK(I6,$I$5:$I$34)) -> 2
B7: =المنتجات!$C$7 -> عصير مدى 33سل | C7: =IF(المنتجات!$C$7="","",SUMIFS('إدخال المشتريات'!$D:$D,'إدخال المشتريات'!$C:$C,المنتجات!$C$7,'إدخال المشتريات'!$B:$B,">="&'لوحة القيادة'!$C$4,'إدخال المشتريات'!$B:$B,"<="&'لوحة القيادة'!$E$4)) -> 1350 | D7: =IF(المنتجات!$C$7="","",SUMIFS('إدخال المشتريات'!$F:$F,'إدخال المشتريات'!$C:$C,المنتجات!$C$7,'إدخال المشتريات'!$B:$B,">="&'لوحة القيادة'!$C$4,'إدخال المشتريات'!$B:$B,"<="&'لوحة القيادة'!$E$4)) -> 432000 | E7: =IF(المنتجات!$C$7="","",IFERROR(SUMIFS('إدخال المشتريات'!$F:$F,'إدخال المشتريات'!$C:$C,المنتجات!$C$7)/SUMIFS('إدخال المشتريات'!$D:$D,'إدخال المشتريات'!$C:$C,المنتجات!$C$7),0)) -> 320 | F7: =IF(المنتجات!$C$7="","",SUMIFS('إدخال المبيعات'!$D:$D,'إدخال المبيعات'!$C:$C,المنتجات!$C$7,'إدخال المبيعات'!$B:$B,">="&'لوحة القيادة'!$C$4,'إدخال المبيعات'!$B:$B,"<="&'لوحة القيادة'!$E$4)) -> 653 | G7: =IF(المنتجات!$C$7="","",SUMIFS('إدخال المبيعات'!$F:$F,'إدخال المبيعات'!$C:$C,المنتجات!$C$7,'إدخال المبيعات'!$B:$B,">="&'لوحة القيادة'!$C$4,'إدخال المبيعات'!$B:$B,"<="&'لوحة القيادة'!$E$4)) -> 261199.7 | H7: =IF(المنتجات!$C$7="","",E7*F7) -> 208960 | I7: =IF(المنتجات!$C$7="","",G7-H7) -> 52239.7 | J7: =IF(OR(المنتجات!$C$7="",G7=0),"",I7/G7) -> 0.19999908 | K7: =IF(المنتجات!$C$7="","",SUMIFS('إدخال المشتريات'!$D:$D,'إدخال المشتريات'!$C:$C,المنتجات!$C$7)-SUMIFS('إدخال المبيعات'!$D:$D,'إدخال المبيعات'!$C:$C,المنتجات!$C$7)) -> 697 | L7: =IF(المنتجات!$C$7="","",IF(K7<=المنتجات!$E$7,"⚠ أعد الطلب","جيد")) -> جيد | M7: =IF(OR(المنتجات!$C$7="",I7=""),"",RANK(I7,$I$5:$I$34)) -> 3
B8: =المنتجات!$C$8 -> عصير اكسترا 2ل | C8: =IF(المنتجات!$C$8="","",SUMIFS('إدخال المشتريات'!$D:$D,'إدخال المشتريات'!$C:$C,المنتجات!$C$8,'إدخال المشتريات'!$B:$B,">="&'لوحة القيادة'!$C$4,'إدخال المشتريات'!$B:$B,"<="&'لوحة القيادة'!$E$4)) -> 320 | D8: =IF(المنتجات!$C$8="","",SUMIFS('إدخال المشتريات'!$F:$F,'إدخال المشتريات'!$C:$C,المنتجات!$C$8,'إدخال المشتريات'!$B:$B,">="&'لوحة القيادة'!$C$4,'إدخال المشتريات'!$B:$B,"<="&'لوحة القيادة'!$E$4)) -> 160000 | E8: =IF(المنتجات!$C$8="","",IFERROR(SUMIFS('إدخال المشتريات'!$F:$F,'إدخال المشتريات'!$C:$C,المنتجات!$C$8)/SUMIFS('إدخال المشتريات'!$D:$D,'إدخال المشتريات'!$C:$C,المنتجات!$C$8),0)) -> 500 | F8: =IF(المنتجات!$C$8="","",SUMIFS('إدخال المبيعات'!$D:$D,'إدخال المبيعات'!$C:$C,المنتجات!$C$8,'إدخال المبيعات'!$B:$B,">="&'لوحة القيادة'!$C$4,'إدخال المبيعات'!$B:$B,"<="&'لوحة القيادة'!$E$4)) -> 316 | G8: =IF(المنتجات!$C$8="","",SUMIFS('إدخال المبيعات'!$F:$F,'إدخال المبيعات'!$C:$C,المنتجات!$C$8,'إدخال المبيعات'!$B:$B,">="&'لوحة القيادة'!$C$4,'إدخال المبيعات'!$B:$B,"<="&'لوحة القيادة'!$E$4)) -> 188980.64 | H8: =IF(المنتجات!$C$8="","",E8*F8) -> 158000 | I8: =IF(المنتجات!$C$8="","",G8-H8) -> 30980.64 | J8: =IF(OR(المنتجات!$C$8="",G8=0),"",I8/G8) -> 0.16393552 | K8: =IF(المنتجات!$C$8="","",SUMIFS('إدخال المشتريات'!$D:$D,'إدخال المشتريات'!$C:$C,المنتجات!$C$8)-SUMIFS('إدخال المبيعات'!$D:$D,'إدخال المبيعات'!$C:$C,المنتجات!$C$8)) -> 4 | L8: =IF(المنتجات!$C$8="","",IF(K8<=المنتجات!$E$8,"⚠ أعد الطلب","جيد")) -> ⚠ أعد الطلب | M8: =IF(OR(المنتجات!$C$8="",I8=""),"",RANK(I8,$I$5:$I$34)) -> 6
B9: =المنتجات!$C$9 -> عصير مدى 1.5ل | C9: =IF(المنتجات!$C$9="","",SUMIFS('إدخال المشتريات'!$D:$D,'إدخال المشتريات'!$C:$C,المنتجات!$C$9,'إدخال المشتريات'!$B:$B,">="&'لوحة القيادة'!$C$4,'إدخال المشتريات'!$B:$B,"<="&'لوحة القيادة'!$E$4)) -> 400 | D9: =IF(المنتجات!$C$9="","",SUMIFS('إدخال المشتريات'!$F:$F,'إدخال المشتريات'!$C:$C,المنتجات!$C$9,'إدخال المشتريات'!$B:$B,">="&'لوحة القيادة'!$C$4,'إدخال المشتريات'!$B:$B,"<="&'لوحة القيادة'!$E$4)) -> 200000 | E9: =IF(المنتجات!$C$9="","",IFERROR(SUMIFS('إدخال المشتريات'!$F:$F,'إدخال المشتريات'!$C:$C,المنتجات!$C$9)/SUMIFS('إدخال المشتريات'!$D:$D,'إدخال المشتريات'!$C:$C,المنتجات!$C$9),0)) -> 500 | F9: =IF(المنتجات!$C$9="","",SUMIFS('إدخال المبيعات'!$D:$D,'إدخال المبيعات'!$C:$C,المنتجات!$C$9,'إدخال المبيعات'!$B:$B,">="&'لوحة القيادة'!$C$4,'إدخال المبيعات'!$B:$B,"<="&'لوحة القيادة'!$E$4)) -> 317 | G9: =IF(المنتجات!$C$9="","",SUMIFS('إدخال المبيعات'!$F:$F,'إدخال المبيعات'!$C:$C,المنتجات!$C$9,'إدخال المبيعات'!$B:$B,">="&'لوحة القيادة'!$C$4,'إدخال المبيعات'!$B:$B,"<="&'لوحة القيادة'!$E$4)) -> 190199.32 | H9: =IF(المنتجات!$C$9="","",E9*F9) -> 158500 | I9: =IF(المنتجات!$C$9="","",G9-H9) -> 31699.32 | J9: =IF(OR(المنتجات!$C$9="",G9=0),"",I9/G9) -> 0.16666369 | K9: =IF(المنتجات!$C$9="","",SUMIFS('إدخال المشتريات'!$D:$D,'إدخال المشتريات'!$C:$C,المنتجات!$C$9)-SUMIFS('إدخال المبيعات'!$D:$D,'إدخال المبيعات'!$C:$C,المنتجات!$C$9)) -> 83 | L9: =IF(المنتجات!$C$9="","",IF(K9<=المنتجات!$E$9,"⚠ أعد الطلب","جيد")) -> جيد | M9: =IF(OR(المنتجات!$C$9="",I9=""),"",RANK(I9,$I$5:$I$34)) -> 5
B10: =المنتجات!$C$10 -> جيليكس 2ل | C10: =IF(المنتجات!$C$10="","",SUMIFS('إدخال المشتريات'!$D:$D,'إدخال المشتريات'!$C:$C,المنتجات!$C$10,'إدخال المشتريات'!$B:$B,">="&'لوحة القيادة'!$C$4,'إدخال المشتريات'!$B:$B,"<="&'لوحة القيادة'!$E$4)) -> 1280 | D10: =IF(المنتجات!$C$10="","",SUMIFS('إدخال المشتريات'!$F:$F,'إدخال المشتريات'!$C:$C,المنتجات!$C$10,'إدخال المشتريات'!$B:$B,">="&'لوحة القيادة'!$C$4,'إدخال المشتريات'!$B:$B,"<="&'لوحة القيادة'!$E$4)) -> 618000 | E10: =IF(المنتجات!$C$10="","",IFERROR(SUMIFS('إدخال المشتريات'!$F:$F,'إدخال المشتريات'!$C:$C,المنتجات!$C$10)/SUMIFS('إدخال المشتريات'!$D:$D,'إدخال المشتريات'!$C:$C,المنتجات!$C$10),0)) -> 482.8125 | F10: =IF(المنتجات!$C$10="","",SUMIFS('إدخال المبيعات'!$D:$D,'إدخال المبيعات'!$C:$C,المنتجات!$C$10,'إدخال المبيعات'!$B:$B,">="&'لوحة القيادة'!$C$4,'إدخال المبيعات'!$B:$B,"<="&'لوحة القيادة'!$E$4)) -> 1033 | G10: =IF(المنتجات!$C$10="","",SUMIFS('إدخال المبيعات'!$F:$F,'إدخال المبيعات'!$C:$C,المنتجات!$C$10,'إدخال المبيعات'!$B:$B,">="&'لوحة القيادة'!$C$4,'إدخال المبيعات'!$B:$B,"<="&'لوحة القيادة'!$E$4)) -> 537160 | H10: =IF(المنتجات!$C$10="","",E10*F10) -> 498745.31 | I10: =IF(المنتجات!$C$10="","",G10-H10) -> 38414.688 | J10: =IF(OR(المنتجات!$C$10="",G10=0),"",I10/G10) -> 0.071514423 | K10: =IF(المنتجات!$C$10="","",SUMIFS('إدخال المشتريات'!$D:$D,'إدخال المشتريات'!$C:$C,المنتجات!$C$10)-SUMIFS('إدخال المبيعات'!$D:$D,'إدخال المبيعات'!$C:$C,المنتجات!$C$10)) -> 247 | L10: =IF(المنتجات!$C$10="","",IF(K10<=المنتجات!$E$10,"⚠ أعد الطلب","جيد")) -> جيد | M10: =IF(OR(المنتجات!$C$10="",I10=""),"",RANK(I10,$I$5:$I$34)) -> 4
B11: =المنتجات!$C$11 -> جي اروى 2ل | C11: =IF(المنتجات!$C$11="","",SUMIFS('إدخال المشتريات'!$D:$D,'إدخال المشتريات'!$C:$C,المنتجات!$C$11,'إدخال المشتريات'!$B:$B,">="&'لوحة القيادة'!$C$4,'إدخال المشتريات'!$B:$B,"<="&'لوحة القيادة'!$E$4)) -> 560 | D11: =IF(المنتجات!$C$11="","",SUMIFS('إدخال المشتريات'!$F:$F,'إدخال المشتريات'!$C:$C,المنتجات!$C$11,'إدخال المشتريات'!$B:$B,">="&'لوحة القيادة'!$C$4,'إدخال المشتريات'!$B:$B,"<="&'لوحة القيادة'!$E$4)) -> 400400 | E11: =IF(المنتجات!$C$11="","",IFERROR(SUMIFS('إدخال المشتريات'!$F:$F,'إدخال المشتريات'!$C:$C,المنتجات!$C$11)/SUMIFS('إدخال المشتريات'!$D:$D,'إدخال المشتريات'!$C:$C,المنتجات!$C$11),0)) -> 715 | F11: =IF(المنتجات!$C$11="","",SUMIFS('إدخال المبيعات'!$D:$D,'إدخال المبيعات'!$C:$C,المنتجات!$C$11,'إدخال المبيعات'!$B:$B,">="&'لوحة القيادة'!$C$4,'إدخال المبيعات'!$B:$B,"<="&'لوحة القيادة'!$E$4)) -> 321 | G11: =IF(المنتجات!$C$11="","",SUMIFS('إدخال المبيعات'!$F:$F,'إدخال المبيعات'!$C:$C,المنتجات!$C$11,'إدخال المبيعات'!$B:$B,">="&'لوحة القيادة'!$C$4,'إدخال المبيعات'!$B:$B,"<="&'لوحة القيادة'!$E$4)) -> 243960 | H11: =IF(المنتجات!$C$11="","",E11*F11) -> 229515 | I11: =IF(المنتجات!$C$11="","",G11-H11) -> 14445 | J11: =IF(OR(المنتجات!$C$11="",G11=0),"",I11/G11) -> 0.059210526 | K11: =IF(المنتجات!$C$11="","",SUMIFS('إدخال المشتريات'!$D:$D,'إدخال المشتريات'!$C:$C,المنتجات!$C$11)-SUMIFS('إدخال المبيعات'!$D:$D,'إدخال المبيعات'!$C:$C,المنتجات!$C$11)) -> 239 | L11: =IF(المنتجات!$C$11="","",IF(K11<=المنتجات!$E$11,"⚠ أعد الطلب","جيد")) -> جيد | M11: =IF(OR(المنتجات!$C$11="",I11=""),"",RANK(I11,$I$5:$I$34)) -> 7
B12: =المنتجات!$C$12 -> اورنجينا 2 لتر | C12: =IF(المنتجات!$C$12="","",SUMIFS('إدخال المشتريات'!$D:$D,'إدخال المشتريات'!$C:$C,المنتجات!$C$12,'إدخال المشتريات'!$B:$B,">="&'لوحة القيادة'!$C$4,'إدخال المشتريات'!$B:$B,"<="&'لوحة القيادة'!$E$4)) -> 560 | D12: =IF(المنتجات!$C$12="","",SUMIFS('إدخال المشتريات'!$F:$F,'إدخال المشتريات'!$C:$C,المنتجات!$C$12,'إدخال المشتريات'!$B:$B,">="&'لوحة القيادة'!$C$4,'إدخال المشتريات'!$B:$B,"<="&'لوحة القيادة'!$E$4)) -> 400400 | E12: =IF(المنتجات!$C$12="","",IFERROR(SUMIFS('إدخال المشتريات'!$F:$F,'إدخال المشتريات'!$C:$C,المنتجات!$C$12)/SUMIFS('إدخال المشتريات'!$D:$D,'إدخال المشتريات'!$C:$C,المنتجات!$C$12),0)) -> 715 | F12: =IF(المنتجات!$C$12="","",SUMIFS('إدخال المبيعات'!$D:$D,'إدخال المبيعات'!$C:$C,المنتجات!$C$12,'إدخال المبيعات'!$B:$B,">="&'لوحة القيادة'!$C$4,'إدخال المبيعات'!$B:$B,"<="&'لوحة القيادة'!$E$4)) -> 315 | G12: =IF(المنتجات!$C$12="","",SUMIFS('إدخال المبيعات'!$F:$F,'إدخال المبيعات'!$C:$C,المنتجات!$C$12,'إدخال المبيعات'!$B:$B,">="&'لوحة القيادة'!$C$4,'إدخال المبيعات'!$B:$B,"<="&'لوحة القيادة'!$E$4)) -> 239400 | H12: =IF(المنتجات!$C$12="","",E12*F12) -> 225225 | I12: =IF(المنتجات!$C$12="","",G12-H12) -> 14175 | J12: =IF(OR(المنتجات!$C$12="",G12=0),"",I12/G12) -> 0.059210526 | K12: =IF(المنتجات!$C$12="","",SUMIFS('إدخال المشتريات'!$D:$D,'إدخال المشتريات'!$C:$C,المنتجات!$C$12)-SUMIFS('إدخال المبيعات'!$D:$D,'إدخال المبيعات'!$C:$C,المنتجات!$C$12)) -> 245 | L12: =IF(المنتجات!$C$12="","",IF(K12<=المنتجات!$E$12,"⚠ أعد الطلب","جيد")) -> جيد | M12: =IF(OR(المنتجات!$C$12="",I12=""),"",RANK(I12,$I$5:$I$34)) -> 8
B13: =المنتجات!$C$13 -> قازوز فرحة 33سل | C13: =IF(المنتجات!$C$13="","",SUMIFS('إدخال المشتريات'!$D:$D,'إدخال المشتريات'!$C:$C,المنتجات!$C$13,'إدخال المشتريات'!$B:$B,">="&'لوحة القيادة'!$C$4,'إدخال المشتريات'!$B:$B,"<="&'لوحة القيادة'!$E$4)) -> 35 | D13: =IF(المنتجات!$C$13="","",SUMIFS('إدخال المشتريات'!$F:$F,'إدخال المشتريات'!$C:$C,المنتجات!$C$13,'إدخال المشتريات'!$B:$B,">="&'لوحة القيادة'!$C$4,'إدخال المشتريات'!$B:$B,"<="&'لوحة القيادة'!$E$4)) -> 7700 | E13: =IF(المنتجات!$C$13="","",IFERROR(SUMIFS('إدخال المشتريات'!$F:$F,'إدخال المشتريات'!$C:$C,المنتجات!$C$13)/SUMIFS('إدخال المشتريات'!$D:$D,'إدخال المشتريات'!$C:$C,المنتجات!$C$13),0)) -> 220 | F13: =IF(المنتجات!$C$13="","",SUMIFS('إدخال المبيعات'!$D:$D,'إدخال المبيعات'!$C:$C,المنتجات!$C$13,'إدخال المبيعات'!$B:$B,">="&'لوحة القيادة'!$C$4,'إدخال المبيعات'!$B:$B,"<="&'لوحة القيادة'!$E$4)) -> 35 | G13: =IF(المنتجات!$C$13="","",SUMIFS('إدخال المبيعات'!$F:$F,'إدخال المبيعات'!$C:$C,المنتجات!$C$13,'إدخال المبيعات'!$B:$B,">="&'لوحة القيادة'!$C$4,'إدخال المبيعات'!$B:$B,"<="&'لوحة القيادة'!$E$4)) -> 9100 | H13: =IF(المنتجات!$C$13="","",E13*F13) -> 7700 | I13: =IF(المنتجات!$C$13="","",G13-H13) -> 1400 | J13: =IF(OR(المنتجات!$C$13="",G13=0),"",I13/G13) -> 0.15384615 | K13: =IF(المنتجات!$C$13="","",SUMIFS('إدخال المشتريات'!$D:$D,'إدخال المشتريات'!$C:$C,المنتجات!$C$13)-SUMIFS('إدخال المبيعات'!$D:$D,'إدخال المبيعات'!$C:$C,المنتجات!$C$13)) -> 0 | L13: =IF(المنتجات!$C$13="","",IF(K13<=المنتجات!$E$13,"⚠ أعد الطلب","جيد")) -> ⚠ أعد الطلب | M13: =IF(OR(المنتجات!$C$13="",I13=""),"",RANK(I13,$I$5:$I$34)) -> 9
B14: =المنتجات!$C$14 -> 0 | C14: =IF(المنتجات!$C$14="","",SUMIFS('إدخال المشتريات'!$D:$D,'إدخال المشتريات'!$C:$C,المنتجات!$C$14,'إدخال المشتريات'!$B:$B,">="&'لوحة القيادة'!$C$4,'إدخال المشتريات'!$B:$B,"<="&'لوحة القيادة'!$E$4)) | D14: =IF(المنتجات!$C$14="","",SUMIFS('إدخال المشتريات'!$F:$F,'إدخال المشتريات'!$C:$C,المنتجات!$C$14,'إدخال المشتريات'!$B:$B,">="&'لوحة القيادة'!$C$4,'إدخال المشتريات'!$B:$B,"<="&'لوحة القيادة'!$E$4)) | E14: =IF(المنتجات!$C$14="","",IFERROR(SUMIFS('إدخال المشتريات'!$F:$F,'إدخال المشتريات'!$C:$C,المنتجات!$C$14)/SUMIFS('إدخال المشتريات'!$D:$D,'إدخال المشتريات'!$C:$C,المنتجات!$C$14),0)) | F14: =IF(المنتجات!$C$14="","",SUMIFS('إدخال المبيعات'!$D:$D,'إدخال المبيعات'!$C:$C,المنتجات!$C$14,'إدخال المبيعات'!$B:$B,">="&'لوحة القيادة'!$C$4,'إدخال المبيعات'!$B:$B,"<="&'لوحة القيادة'!$E$4)) | G14: =IF(المنتجات!$C$14="","",SUMIFS('إدخال المبيعات'!$F:$F,'إدخال المبيعات'!$C:$C,المنتجات!$C$14,'إدخال المبيعات'!$B:$B,">="&'لوحة القيادة'!$C$4,'إدخال المبيعات'!$B:$B,"<="&'لوحة القيادة'!$E$4)) | H14: =IF(المنتجات!$C$14="","",E14*F14) | I14: =IF(المنتجات!$C$14="","",G14-H14) | J14: =IF(OR(المنتجات!$C$14="",G14=0),"",I14/G14) | K14: =IF(المنتجات!$C$14="","",SUMIFS('إدخال المشتريات'!$D:$D,'إدخال المشتريات'!$C:$C,المنتجات!$C$14)-SUMIFS('إدخال المبيعات'!$D:$D,'إدخال المبيعات'!$C:$C,المنتجات!$C$14)) | L14: =IF(المنتجات!$C$14="","",IF(K14<=المنتجات!$E$14,"⚠ أعد الطلب","جيد")) | M14: =IF(OR(المنتجات!$C$14="",I14=""),"",RANK(I14,$I$5:$I$34))
B15: =المنتجات!$C$15 -> 0 | C15: =IF(المنتجات!$C$15="","",SUMIFS('إدخال المشتريات'!$D:$D,'إدخال المشتريات'!$C:$C,المنتجات!$C$15,'إدخال المشتريات'!$B:$B,">="&'لوحة القيادة'!$C$4,'إدخال المشتريات'!$B:$B,"<="&'لوحة القيادة'!$E$4)) | D15: =IF(المنتجات!$C$15="","",SUMIFS('إدخال المشتريات'!$F:$F,'إدخال المشتريات'!$C:$C,المنتجات!$C$15,'إدخال المشتريات'!$B:$B,">="&'لوحة القيادة'!$C$4,'إدخال المشتريات'!$B:$B,"<="&'لوحة القيادة'!$E$4)) | E15: =IF(المنتجات!$C$15="","",IFERROR(SUMIFS('إدخال المشتريات'!$F:$F,'إدخال المشتريات'!$C:$C,المنتجات!$C$15)/SUMIFS('إدخال المشتريات'!$D:$D,'إدخال المشتريات'!$C:$C,المنتجات!$C$15),0)) | F15: =IF(المنتجات!$C$15="","",SUMIFS('إدخال المبيعات'!$D:$D,'إدخال المبيعات'!$C:$C,المنتجات!$C$15,'إدخال المبيعات'!$B:$B,">="&'لوحة القيادة'!$C$4,'إدخال المبيعات'!$B:$B,"<="&'لوحة القيادة'!$E$4)) | G15: =IF(المنتجات!$C$15="","",SUMIFS('إدخال المبيعات'!$F:$F,'إدخال المبيعات'!$C:$C,المنتجات!$C$15,'إدخال المبيعات'!$B:$B,">="&'لوحة القيادة'!$C$4,'إدخال المبيعات'!$B:$B,"<="&'لوحة القيادة'!$E$4)) | H15: =IF(المنتجات!$C$15="","",E15*F15) | I15: =IF(المنتجات!$C$15="","",G15-H15) | J15: =IF(OR(المنتجات!$C$15="",G15=0),"",I15/G15) | K15: =IF(المنتجات!$C$15="","",SUMIFS('إدخال المشتريات'!$D:$D,'إدخال المشتريات'!$C:$C,المنتجات!$C$15)-SUMIFS('إدخال المبيعات'!$D:$D,'إدخال المبيعات'!$C:$C,المنتجات!$C$15)) | L15: =IF(المنتجات!$C$15="","",IF(K15<=المنتجات!$E$15,"⚠ أعد الطلب","جيد")) | M15: =IF(OR(المنتجات!$C$15="",I15=""),"",RANK(I15,$I$5:$I$34))
B16: =المنتجات!$C$16 -> 0 | C16: =IF(المنتجات!$C$16="","",SUMIFS('إدخال المشتريات'!$D:$D,'إدخال المشتريات'!$C:$C,المنتجات!$C$16,'إدخال المشتريات'!$B:$B,">="&'لوحة القيادة'!$C$4,'إدخال المشتريات'!$B:$B,"<="&'لوحة القيادة'!$E$4)) | D16: =IF(المنتجات!$C$16="","",SUMIFS('إدخال المشتريات'!$F:$F,'إدخال المشتريات'!$C:$C,المنتجات!$C$16,'إدخال المشتريات'!$B:$B,">="&'لوحة القيادة'!$C$4,'إدخال المشتريات'!$B:$B,"<="&'لوحة القيادة'!$E$4)) | E16: =IF(المنتجات!$C$16="","",IFERROR(SUMIFS('إدخال المشتريات'!$F:$F,'إدخال المشتريات'!$C:$C,المنتجات!$C$16)/SUMIFS('إدخال المشتريات'!$D:$D,'إدخال المشتريات'!$C:$C,المنتجات!$C$16),0)) | F16: =IF(المنتجات!$C$16="","",SUMIFS('إدخال المبيعات'!$D:$D,'إدخال المبيعات'!$C:$C,المنتجات!$C$16,'إدخال المبيعات'!$B:$B,">="&'لوحة القيادة'!$C$4,'إدخال المبيعات'!$B:$B,"<="&'لوحة القيادة'!$E$4)) | G16: =IF(المنتجات!$C$16="","",SUMIFS('إدخال المبيعات'!$F:$F,'إدخال المبيعات'!$C:$C,المنتجات!$C$16,'إدخال المبيعات'!$B:$B,">="&'لوحة القيادة'!$C$4,'إدخال المبيعات'!$B:$B,"<="&'لوحة القيادة'!$E$4)) | H16: =IF(المنتجات!$C$16="","",E16*F16) | I16: =IF(المنتجات!$C$16="","",G16-H16) | J16: =IF(OR(المنتجات!$C$16="",G16=0),"",I16/G16) | K16: =IF(المنتجات!$C$16="","",SUMIFS('إدخال المشتريات'!$D:$D,'إدخال المشتريات'!$C:$C,المنتجات!$C$16)-SUMIFS('إدخال المبيعات'!$D:$D,'إدخال المبيعات'!$C:$C,المنتجات!$C$16)) | L16: =IF(المنتجات!$C$16="","",IF(K16<=المنتجات!$E$16,"⚠ أعد الطلب","جيد")) | M16: =IF(OR(المنتجات!$C$16="",I16=""),"",RANK(I16,$I$5:$I$34))
B17: =المنتجات!$C$17 -> 0 | C17: =IF(المنتجات!$C$17="","",SUMIFS('إدخال المشتريات'!$D:$D,'إدخال المشتريات'!$C:$C,المنتجات!$C$17,'إدخال المشتريات'!$B:$B,">="&'لوحة القيادة'!$C$4,'إدخال المشتريات'!$B:$B,"<="&'لوحة القيادة'!$E$4)) | D17: =IF(المنتجات!$C$17="","",SUMIFS('إدخال المشتريات'!$F:$F,'إدخال المشتريات'!$C:$C,المنتجات!$C$17,'إدخال المشتريات'!$B:$B,">="&'لوحة القيادة'!$C$4,'إدخال المشتريات'!$B:$B,"<="&'لوحة القيادة'!$E$4)) | E17: =IF(المنتجات!$C$17="","",IFERROR(SUMIFS('إدخال المشتريات'!$F:$F,'إدخال المشتريات'!$C:$C,المنتجات!$C$17)/SUMIFS('إدخال المشتريات'!$D:$D,'إدخال المشتريات'!$C:$C,المنتجات!$C$17),0)) | F17: =IF(المنتجات!$C$17="","",SUMIFS('إدخال المبيعات'!$D:$D,'إدخال المبيعات'!$C:$C,المنتجات!$C$17,'إدخال المبيعات'!$B:$B,">="&'لوحة القيادة'!$C$4,'إدخال المبيعات'!$B:$B,"<="&'لوحة القيادة'!$E$4)) | G17: =IF(المنتجات!$C$17="","",SUMIFS('إدخال المبيعات'!$F:$F,'إدخال المبيعات'!$C:$C,المنتجات!$C$17,'إدخال المبيعات'!$B:$B,">="&'لوحة القيادة'!$C$4,'إدخال المبيعات'!$B:$B,"<="&'لوحة القيادة'!$E$4)) | H17: =IF(المنتجات!$C$17="","",E17*F17) | I17: =IF(المنتجات!$C$17="","",G17-H17) | J17: =IF(OR(المنتجات!$C$17="",G17=0),"",I17/G17) | K17: =IF(المنتجات!$C$17="","",SUMIFS('إدخال المشتريات'!$D:$D,'إدخال المشتريات'!$C:$C,المنتجات!$C$17)-SUMIFS('إدخال المبيعات'!$D:$D,'إدخال المبيعات'!$C:$C,المنتجات!$C$17)) | L17: =IF(المنتجات!$C$17="","",IF(K17<=المنتجات!$E$17,"⚠ أعد الطلب","جيد")) | M17: =IF(OR(المنتجات!$C$17="",I17=""),"",RANK(I17,$I$5:$I$34))
B18: =المنتجات!$C$18 -> 0 | C18: =IF(المنتجات!$C$18="","",SUMIFS('إدخال المشتريات'!$D:$D,'إدخال المشتريات'!$C:$C,المنتجات!$C$18,'إدخال المشتريات'!$B:$B,">="&'لوحة القيادة'!$C$4,'إدخال المشتريات'!$B:$B,"<="&'لوحة القيادة'!$E$4)) | D18: =IF(المنتجات!$C$18="","",SUMIFS('إدخال المشتريات'!$F:$F,'إدخال المشتريات'!$C:$C,المنتجات!$C$18,'إدخال المشتريات'!$B:$B,">="&'لوحة القيادة'!$C$4,'إدخال المشتريات'!$B:$B,"<="&'لوحة القيادة'!$E$4)) | E18: =IF(المنتجات!$C$18="","",IFERROR(SUMIFS('إدخال المشتريات'!$F:$F,'إدخال المشتريات'!$C:$C,المنتجات!$C$18)/SUMIFS('إدخال المشتريات'!$D:$D,'إدخال المشتريات'!$C:$C,المنتجات!$C$18),0)) | F18: =IF(المنتجات!$C$18="","",SUMIFS('إدخال المبيعات'!$D:$D,'إدخال المبيعات'!$C:$C,المنتجات!$C$18,'إدخال المبيعات'!$B:$B,">="&'لوحة القيادة'!$C$4,'إدخال المبيعات'!$B:$B,"<="&'لوحة القيادة'!$E$4)) | G18: =IF(المنتجات!$C$18="","",SUMIFS('إدخال المبيعات'!$F:$F,'إدخال المبيعات'!$C:$C,المنتجات!$C$18,'إدخال المبيعات'!$B:$B,">="&'لوحة القيادة'!$C$4,'إدخال المبيعات'!$B:$B,"<="&'لوحة القيادة'!$E$4)) | H18: =IF(المنتجات!$C$18="","",E18*F18) | I18: =IF(المنتجات!$C$18="","",G18-H18) | J18: =IF(OR(المنتجات!$C$18="",G18=0),"",I18/G18) | K18: =IF(المنتجات!$C$18="","",SUMIFS('إدخال المشتريات'!$D:$D,'إدخال المشتريات'!$C:$C,المنتجات!$C$18)-SUMIFS('إدخال المبيعات'!$D:$D,'إدخال المبيعات'!$C:$C,المنتجات!$C$18)) | L18: =IF(المنتجات!$C$18="","",IF(K18<=المنتجات!$E$18,"⚠ أعد الطلب","جيد")) | M18: =IF(OR(المنتجات!$C$18="",I18=""),"",RANK(I18,$I$5:$I$34))
B19: =المنتجات!$C$19 -> 0 | C19: =IF(المنتجات!$C$19="","",SUMIFS('إدخال المشتريات'!$D:$D,'إدخال المشتريات'!$C:$C,المنتجات!$C$19,'إدخال المشتريات'!$B:$B,">="&'لوحة القيادة'!$C$4,'إدخال المشتريات'!$B:$B,"<="&'لوحة القيادة'!$E$4)) | D19: =IF(المنتجات!$C$19="","",SUMIFS('إدخال المشتريات'!$F:$F,'إدخال المشتريات'!$C:$C,المنتجات!$C$19,'إدخال المشتريات'!$B:$B,">="&'لوحة القيادة'!$C$4,'إدخال المشتريات'!$B:$B,"<="&'لوحة القيادة'!$E$4)) | E19: =IF(المنتجات!$C$19="","",IFERROR(SUMIFS('إدخال المشتريات'!$F:$F,'إدخال المشتريات'!$C:$C,المنتجات!$C$19)/SUMIFS('إدخال المشتريات'!$D:$D,'إدخال المشتريات'!$C:$C,المنتجات!$C$19),0)) | F19: =IF(المنتجات!$C$19="","",SUMIFS('إدخال المبيعات'!$D:$D,'إدخال المبيعات'!$C:$C,المنتجات!$C$19,'إدخال المبيعات'!$B:$B,">="&'لوحة القيادة'!$C$4,'إدخال المبيعات'!$B:$B,"<="&'لوحة القيادة'!$E$4)) | G19: =IF(المنتجات!$C$19="","",SUMIFS('إدخال المبيعات'!$F:$F,'إدخال المبيعات'!$C:$C,المنتجات!$C$19,'إدخال المبيعات'!$B:$B,">="&'لوحة القيادة'!$C$4,'إدخال المبيعات'!$B:$B,"<="&'لوحة القيادة'!$E$4)) | H19: =IF(المنتجات!$C$19="","",E19*F19) | I19: =IF(المنتجات!$C$19="","",G19-H19) | J19: =IF(OR(المنتجات!$C$19="",G19=0),"",I19/G19) | K19: =IF(المنتجات!$C$19="","",SUMIFS('إدخال المشتريات'!$D:$D,'إدخال المشتريات'!$C:$C,المنتجات!$C$19)-SUMIFS('إدخال المبيعات'!$D:$D,'إدخال المبيعات'!$C:$C,المنتجات!$C$19)) | L19: =IF(المنتجات!$C$19="","",IF(K19<=المنتجات!$E$19,"⚠ أعد الطلب","جيد")) | M19: =IF(OR(المنتجات!$C$19="",I19=""),"",RANK(I19,$I$5:$I$34))
B20: =المنتجات!$C$20 -> 0 | C20: =IF(المنتجات!$C$20="","",SUMIFS('إدخال المشتريات'!$D:$D,'إدخال المشتريات'!$C:$C,المنتجات!$C$20,'إدخال المشتريات'!$B:$B,">="&'لوحة القيادة'!$C$4,'إدخال المشتريات'!$B:$B,"<="&'لوحة القيادة'!$E$4)) | D20: =IF(المنتجات!$C$20="","",SUMIFS('إدخال المشتريات'!$F:$F,'إدخال المشتريات'!$C:$C,المنتجات!$C$20,'إدخال المشتريات'!$B:$B,">="&'لوحة القيادة'!$C$4,'إدخال المشتريات'!$B:$B,"<="&'لوحة القيادة'!$E$4)) | E20: =IF(المنتجات!$C$20="","",IFERROR(SUMIFS('إدخال المشتريات'!$F:$F,'إدخال المشتريات'!$C:$C,المنتجات!$C$20)/SUMIFS('إدخال المشتريات'!$D:$D,'إدخال المشتريات'!$C:$C,المنتجات!$C$20),0)) | F20: =IF(المنتجات!$C$20="","",SUMIFS('إدخال المبيعات'!$D:$D,'إدخال المبيعات'!$C:$C,المنتجات!$C$20,'إدخال المبيعات'!$B:$B,">="&'لوحة القيادة'!$C$4,'إدخال المبيعات'!$B:$B,"<="&'لوحة القيادة'!$E$4)) | G20: =IF(المنتجات!$C$20="","",SUMIFS('إدخال المبيعات'!$F:$F,'إدخال المبيعات'!$C:$C,المنتجات!$C$20,'إدخال المبيعات'!$B:$B,">="&'لوحة القيادة'!$C$4,'إدخال المبيعات'!$B:$B,"<="&'لوحة القيادة'!$E$4)) | H20: =IF(المنتجات!$C$20="","",E20*F20) | I20: =IF(المنتجات!$C$20="","",G20-H20) | J20: =IF(OR(المنتجات!$C$20="",G20=0),"",I20/G20) | K20: =IF(المنتجات!$C$20="","",SUMIFS('إدخال المشتريات'!$D:$D,'إدخال المشتريات'!$C:$C,المنتجات!$C$20)-SUMIFS('إدخال المبيعات'!$D:$D,'إدخال المبيعات'!$C:$C,المنتجات!$C$20)) | L20: =IF(المنتجات!$C$20="","",IF(K20<=المنتجات!$E$20,"⚠ أعد الطلب","جيد")) | M20: =IF(OR(المنتجات!$C$20="",I20=""),"",RANK(I20,$I$5:$I$34))
B21: =المنتجات!$C$21 -> 0 | C21: =IF(المنتجات!$C$21="","",SUMIFS('إدخال المشتريات'!$D:$D,'إدخال المشتريات'!$C:$C,المنتجات!$C$21,'إدخال المشتريات'!$B:$B,">="&'لوحة القيادة'!$C$4,'إدخال المشتريات'!$B:$B,"<="&'لوحة القيادة'!$E$4)) | D21: =IF(المنتجات!$C$21="","",SUMIFS('إدخال المشتريات'!$F:$F,'إدخال المشتريات'!$C:$C,المنتجات!$C$21,'إدخال المشتريات'!$B:$B,">="&'لوحة القيادة'!$C$4,'إدخال المشتريات'!$B:$B,"<="&'لوحة القيادة'!$E$4)) | E21: =IF(المنتجات!$C$21="","",IFERROR(SUMIFS('إدخال المشتريات'!$F:$F,'إدخال المشتريات'!$C:$C,المنتجات!$C$21)/SUMIFS('إدخال المشتريات'!$D:$D,'إدخال المشتريات'!$C:$C,المنتجات!$C$21),0)) | F21: =IF(المنتجات!$C$21="","",SUMIFS('إدخال المبيعات'!$D:$D,'إدخال المبيعات'!$C:$C,المنتجات!$C$21,'إدخال المبيعات'!$B:$B,">="&'لوحة القيادة'!$C$4,'إدخال المبيعات'!$B:$B,"<="&'لوحة القيادة'!$E$4)) | G21: =IF(المنتجات!$C$21="","",SUMIFS('إدخال المبيعات'!$F:$F,'إدخال المبيعات'!$C:$C,المنتجات!$C$21,'إدخال المبيعات'!$B:$B,">="&'لوحة القيادة'!$C$4,'إدخال المبيعات'!$B:$B,"<="&'لوحة القيادة'!$E$4)) | H21: =IF(المنتجات!$C$21="","",E21*F21) | I21: =IF(المنتجات!$C$21="","",G21-H21) | J21: =IF(OR(المنتجات!$C$21="",G21=0),"",I21/G21) | K21: =IF(المنتجات!$C$21="","",SUMIFS('إدخال المشتريات'!$D:$D,'إدخال المشتريات'!$C:$C,المنتجات!$C$21)-SUMIFS('إدخال المبيعات'!$D:$D,'إدخال المبيعات'!$C:$C,المنتجات!$C$21)) | L21: =IF(المنتجات!$C$21="","",IF(K21<=المنتجات!$E$21,"⚠ أعد الطلب","جيد")) | M21: =IF(OR(المنتجات!$C$21="",I21=""),"",RANK(I21,$I$5:$I$34))
B22: =المنتجات!$C$22 -> 0 | C22: =IF(المنتجات!$C$22="","",SUMIFS('إدخال المشتريات'!$D:$D,'إدخال المشتريات'!$C:$C,المنتجات!$C$22,'إدخال المشتريات'!$B:$B,">="&'لوحة القيادة'!$C$4,'إدخال المشتريات'!$B:$B,"<="&'لوحة القيادة'!$E$4)) | D22: =IF(المنتجات!$C$22="","",SUMIFS('إدخال المشتريات'!$F:$F,'إدخال المشتريات'!$C:$C,المنتجات!$C$22,'إدخال المشتريات'!$B:$B,">="&'لوحة القيادة'!$C$4,'إدخال المشتريات'!$B:$B,"<="&'لوحة القيادة'!$E$4)) | E22: =IF(المنتجات!$C$22="","",IFERROR(SUMIFS('إدخال المشتريات'!$F:$F,'إدخال المشتريات'!$C:$C,المنتجات!$C$22)/SUMIFS('إدخال المشتريات'!$D:$D,'إدخال المشتريات'!$C:$C,المنتجات!$C$22),0)) | F22: =IF(المنتجات!$C$22="","",SUMIFS('إدخال المبيعات'!$D:$D,'إدخال المبيعات'!$C:$C,المنتجات!$C$22,'إدخال المبيعات'!$B:$B,">="&'لوحة القيادة'!$C$4,'إدخال المبيعات'!$B:$B,"<="&'لوحة القيادة'!$E$4)) | G22: =IF(المنتجات!$C$22="","",SUMIFS('إدخال المبيعات'!$F:$F,'إدخال المبيعات'!$C:$C,المنتجات!$C$22,'إدخال المبيعات'!$B:$B,">="&'لوحة القيادة'!$C$4,'إدخال المبيعات'!$B:$B,"<="&'لوحة القيادة'!$E$4)) | H22: =IF(المنتجات!$C$22="","",E22*F22) | I22: =IF(المنتجات!$C$22="","",G22-H22) | J22: =IF(OR(المنتجات!$C$22="",G22=0),"",I22/G22) | K22: =IF(المنتجات!$C$22="","",SUMIFS('إدخال المشتريات'!$D:$D,'إدخال المشتريات'!$C:$C,المنتجات!$C$22)-SUMIFS('إدخال المبيعات'!$D:$D,'إدخال المبيعات'!$C:$C,المنتجات!$C$22)) | L22: =IF(المنتجات!$C$22="","",IF(K22<=المنتجات!$E$22,"⚠ أعد الطلب","جيد")) | M22: =IF(OR(المنتجات!$C$22="",I22=""),"",RANK(I22,$I$5:$I$34))
B23: =المنتجات!$C$23 -> 0 | C23: =IF(المنتجات!$C$23="","",SUMIFS('إدخال المشتريات'!$D:$D,'إدخال المشتريات'!$C:$C,المنتجات!$C$23,'إدخال المشتريات'!$B:$B,">="&'لوحة القيادة'!$C$4,'إدخال المشتريات'!$B:$B,"<="&'لوحة القيادة'!$E$4)) | D23: =IF(المنتجات!$C$23="","",SUMIFS('إدخال المشتريات'!$F:$F,'إدخال المشتريات'!$C:$C,المنتجات!$C$23,'إدخال المشتريات'!$B:$B,">="&'لوحة القيادة'!$C$4,'إدخال المشتريات'!$B:$B,"<="&'لوحة القيادة'!$E$4)) | E23: =IF(المنتجات!$C$23="","",IFERROR(SUMIFS('إدخال المشتريات'!$F:$F,'إدخال المشتريات'!$C:$C,المنتجات!$C$23)/SUMIFS('إدخال المشتريات'!$D:$D,'إدخال المشتريات'!$C:$C,المنتجات!$C$23),0)) | F23: =IF(المنتجات!$C$23="","",SUMIFS('إدخال المبيعات'!$D:$D,'إدخال المبيعات'!$C:$C,المنتجات!$C$23,'إدخال المبيعات'!$B:$B,">="&'لوحة القيادة'!$C$4,'إدخال المبيعات'!$B:$B,"<="&'لوحة القيادة'!$E$4)) | G23: =IF(المنتجات!$C$23="","",SUMIFS('إدخال المبيعات'!$F:$F,'إدخال المبيعات'!$C:$C,المنتجات!$C$23,'إدخال المبيعات'!$B:$B,">="&'لوحة القيادة'!$C$4,'إدخال المبيعات'!$B:$B,"<="&'لوحة القيادة'!$E$4)) | H23: =IF(المنتجات!$C$23="","",E23*F23) | I23: =IF(المنتجات!$C$23="","",G23-H23) | J23: =IF(OR(المنتجات!$C$23="",G23=0),"",I23/G23) | K23: =IF(المنتجات!$C$23="","",SUMIFS('إدخال المشتريات'!$D:$D,'إدخال المشتريات'!$C:$C,المنتجات!$C$23)-SUMIFS('إدخال المبيعات'!$D:$D,'إدخال المبيعات'!$C:$C,المنتجات!$C$23)) | L23: =IF(المنتجات!$C$23="","",IF(K23<=المنتجات!$E$23,"⚠ أعد الطلب","جيد")) | M23: =IF(OR(المنتجات!$C$23="",I23=""),"",RANK(I23,$I$5:$I$34))
B24: =المنتجات!$C$24 -> 0 | C24: =IF(المنتجات!$C$24="","",SUMIFS('إدخال المشتريات'!$D:$D,'إدخال المشتريات'!$C:$C,المنتجات!$C$24,'إدخال المشتريات'!$B:$B,">="&'لوحة القيادة'!$C$4,'إدخال المشتريات'!$B:$B,"<="&'لوحة القيادة'!$E$4)) | D24: =IF(المنتجات!$C$24="","",SUMIFS('إدخال المشتريات'!$F:$F,'إدخال المشتريات'!$C:$C,المنتجات!$C$24,'إدخال المشتريات'!$B:$B,">="&'لوحة القيادة'!$C$4,'إدخال المشتريات'!$B:$B,"<="&'لوحة القيادة'!$E$4)) | E24: =IF(المنتجات!$C$24="","",IFERROR(SUMIFS('إدخال المشتريات'!$F:$F,'إدخال المشتريات'!$C:$C,المنتجات!$C$24)/SUMIFS('إدخال المشتريات'!$D:$D,'إدخال المشتريات'!$C:$C,المنتجات!$C$24),0)) | F24: =IF(المنتجات!$C$24="","",SUMIFS('إدخال المبيعات'!$D:$D,'إدخال المبيعات'!$C:$C,المنتجات!$C$24,'إدخال المبيعات'!$B:$B,">="&'لوحة القيادة'!$C$4,'إدخال المبيعات'!$B:$B,"<="&'لوحة القيادة'!$E$4)) | G24: =IF(المنتجات!$C$24="","",SUMIFS('إدخال المبيعات'!$F:$F,'إدخال المبيعات'!$C:$C,المنتجات!$C$24,'إدخال المبيعات'!$B:$B,">="&'لوحة القيادة'!$C$4,'إدخال المبيعات'!$B:$B,"<="&'لوحة القيادة'!$E$4)) | H24: =IF(المنتجات!$C$24="","",E24*F24) | I24: =IF(المنتجات!$C$24="","",G24-H24) | J24: =IF(OR(المنتجات!$C$24="",G24=0),"",I24/G24) | K24: =IF(المنتجات!$C$24="","",SUMIFS('إدخال المشتريات'!$D:$D,'إدخال المشتريات'!$C:$C,المنتجات!$C$24)-SUMIFS('إدخال المبيعات'!$D:$D,'إدخال المبيعات'!$C:$C,المنتجات!$C$24)) | L24: =IF(المنتجات!$C$24="","",IF(K24<=المنتجات!$E$24,"⚠ أعد الطلب","جيد")) | M24: =IF(OR(المنتجات!$C$24="",I24=""),"",RANK(I24,$I$5:$I$34))
B25: =المنتجات!$C$25 -> 0 | C25: =IF(المنتجات!$C$25="","",SUMIFS('إدخال المشتريات'!$D:$D,'إدخال المشتريات'!$C:$C,المنتجات!$C$25,'إدخال المشتريات'!$B:$B,">="&'لوحة القيادة'!$C$4,'إدخال المشتريات'!$B:$B,"<="&'لوحة القيادة'!$E$4)) | D25: =IF(المنتجات!$C$25="","",SUMIFS('إدخال المشتريات'!$F:$F,'إدخال المشتريات'!$C:$C,المنتجات!$C$25,'إدخال المشتريات'!$B:$B,">="&'لوحة القيادة'!$C$4,'إدخال المشتريات'!$B:$B,"<="&'لوحة القيادة'!$E$4)) | E25: =IF(المنتجات!$C$25="","",IFERROR(SUMIFS('إدخال المشتريات'!$F:$F,'إدخال المشتريات'!$C:$C,المنتجات!$C$25)/SUMIFS('إدخال المشتريات'!$D:$D,'إدخال المشتريات'!$C:$C,المنتجات!$C$25),0)) | F25: =IF(المنتجات!$C$25="","",SUMIFS('إدخال المبيعات'!$D:$D,'إدخال المبيعات'!$C:$C,المنتجات!$C$25,'إدخال المبيعات'!$B:$B,">="&'لوحة القيادة'!$C$4,'إدخال المبيعات'!$B:$B,"<="&'لوحة القيادة'!$E$4)) | G25: =IF(المنتجات!$C$25="","",SUMIFS('إدخال المبيعات'!$F:$F,'إدخال المبيعات'!$C:$C,المنتجات!$C$25,'إدخال المبيعات'!$B:$B,">="&'لوحة القيادة'!$C$4,'إدخال المبيعات'!$B:$B,"<="&'لوحة القيادة'!$E$4)) | H25: =IF(المنتجات!$C$25="","",E25*F25) | I25: =IF(المنتجات!$C$25="","",G25-H25) | J25: =IF(OR(المنتجات!$C$25="",G25=0),"",I25/G25) | K25: =IF(المنتجات!$C$25="","",SUMIFS('إدخال المشتريات'!$D:$D,'إدخال المشتريات'!$C:$C,المنتجات!$C$25)-SUMIFS('إدخال المبيعات'!$D:$D,'إدخال المبيعات'!$C:$C,المنتجات!$C$25)) | L25: =IF(المنتجات!$C$25="","",IF(K25<=المنتجات!$E$25,"⚠ أعد الطلب","جيد")) | M25: =IF(OR(المنتجات!$C$25="",I25=""),"",RANK(I25,$I$5:$I$34))
B26: =المنتجات!$C$26 -> 0 | C26: =IF(المنتجات!$C$26="","",SUMIFS('إدخال المشتريات'!$D:$D,'إدخال المشتريات'!$C:$C,المنتجات!$C$26,'إدخال المشتريات'!$B:$B,">="&'لوحة القيادة'!$C$4,'إدخال المشتريات'!$B:$B,"<="&'لوحة القيادة'!$E$4)) | D26: =IF(المنتجات!$C$26="","",SUMIFS('إدخال المشتريات'!$F:$F,'إدخال المشتريات'!$C:$C,المنتجات!$C$26,'إدخال المشتريات'!$B:$B,">="&'لوحة القيادة'!$C$4,'إدخال المشتريات'!$B:$B,"<="&'لوحة القيادة'!$E$4)) | E26: =IF(المنتجات!$C$26="","",IFERROR(SUMIFS('إدخال المشتريات'!$F:$F,'إدخال المشتريات'!$C:$C,المنتجات!$C$26)/SUMIFS('إدخال المشتريات'!$D:$D,'إدخال المشتريات'!$C:$C,المنتجات!$C$26),0)) | F26: =IF(المنتجات!$C$26="","",SUMIFS('إدخال المبيعات'!$D:$D,'إدخال المبيعات'!$C:$C,المنتجات!$C$26,'إدخال المبيعات'!$B:$B,">="&'لوحة القيادة'!$C$4,'إدخال المبيعات'!$B:$B,"<="&'لوحة القيادة'!$E$4)) | G26: =IF(المنتجات!$C$26="","",SUMIFS('إدخال المبيعات'!$F:$F,'إدخال المبيعات'!$C:$C,المنتجات!$C$26,'إدخال المبيعات'!$B:$B,">="&'لوحة القيادة'!$C$4,'إدخال المبيعات'!$B:$B,"<="&'لوحة القيادة'!$E$4)) | H26: =IF(المنتجات!$C$26="","",E26*F26) | I26: =IF(المنتجات!$C$26="","",G26-H26) | J26: =IF(OR(المنتجات!$C$26="",G26=0),"",I26/G26) | K26: =IF(المنتجات!$C$26="","",SUMIFS('إدخال المشتريات'!$D:$D,'إدخال المشتريات'!$C:$C,المنتجات!$C$26)-SUMIFS('إدخال المبيعات'!$D:$D,'إدخال المبيعات'!$C:$C,المنتجات!$C$26)) | L26: =IF(المنتجات!$C$26="","",IF(K26<=المنتجات!$E$26,"⚠ أعد الطلب","جيد")) | M26: =IF(OR(المنتجات!$C$26="",I26=""),"",RANK(I26,$I$5:$I$34))
B27: =المنتجات!$C$27 -> 0 | C27: =IF(المنتجات!$C$27="","",SUMIFS('إدخال المشتريات'!$D:$D,'إدخال المشتريات'!$C:$C,المنتجات!$C$27,'إدخال المشتريات'!$B:$B,">="&'لوحة القيادة'!$C$4,'إدخال المشتريات'!$B:$B,"<="&'لوحة القيادة'!$E$4)) | D27: =IF(المنتجات!$C$27="","",SUMIFS('إدخال المشتريات'!$F:$F,'إدخال المشتريات'!$C:$C,المنتجات!$C$27,'إدخال المشتريات'!$B:$B,">="&'لوحة القيادة'!$C$4,'إدخال المشتريات'!$B:$B,"<="&'لوحة القيادة'!$E$4)) | E27: =IF(المنتجات!$C$27="","",IFERROR(SUMIFS('إدخال المشتريات'!$F:$F,'إدخال المشتريات'!$C:$C,المنتجات!$C$27)/SUMIFS('إدخال المشتريات'!$D:$D,'إدخال المشتريات'!$C:$C,المنتجات!$C$27),0)) | F27: =IF(المنتجات!$C$27="","",SUMIFS('إدخال المبيعات'!$D:$D,'إدخال المبيعات'!$C:$C,المنتجات!$C$27,'إدخال المبيعات'!$B:$B,">="&'لوحة القيادة'!$C$4,'إدخال المبيعات'!$B:$B,"<="&'لوحة القيادة'!$E$4)) | G27: =IF(المنتجات!$C$27="","",SUMIFS('إدخال المبيعات'!$F:$F,'إدخال المبيعات'!$C:$C,المنتجات!$C$27,'إدخال المبيعات'!$B:$B,">="&'لوحة القيادة'!$C$4,'إدخال المبيعات'!$B:$B,"<="&'لوحة القيادة'!$E$4)) | H27: =IF(المنتجات!$C$27="","",E27*F27) | I27: =IF(المنتجات!$C$27="","",G27-H27) | J27: =IF(OR(المنتجات!$C$27="",G27=0),"",I27/G27) | K27: =IF(المنتجات!$C$27="","",SUMIFS('إدخال المشتريات'!$D:$D,'إدخال المشتريات'!$C:$C,المنتجات!$C$27)-SUMIFS('إدخال المبيعات'!$D:$D,'إدخال المبيعات'!$C:$C,المنتجات!$C$27)) | L27: =IF(المنتجات!$C$27="","",IF(K27<=المنتجات!$E$27,"⚠ أعد الطلب","جيد")) | M27: =IF(OR(المنتجات!$C$27="",I27=""),"",RANK(I27,$I$5:$I$34))
B28: =المنتجات!$C$28 -> 0 | C28: =IF(المنتجات!$C$28="","",SUMIFS('إدخال المشتريات'!$D:$D,'إدخال المشتريات'!$C:$C,المنتجات!$C$28,'إدخال المشتريات'!$B:$B,">="&'لوحة القيادة'!$C$4,'إدخال المشتريات'!$B:$B,"<="&'لوحة القيادة'!$E$4)) | D28: =IF(المنتجات!$C$28="","",SUMIFS('إدخال المشتريات'!$F:$F,'إدخال المشتريات'!$C:$C,المنتجات!$C$28,'إدخال المشتريات'!$B:$B,">="&'لوحة القيادة'!$C$4,'إدخال المشتريات'!$B:$B,"<="&'لوحة القيادة'!$E$4)) | E28: =IF(المنتجات!$C$28="","",IFERROR(SUMIFS('إدخال المشتريات'!$F:$F,'إدخال المشتريات'!$C:$C,المنتجات!$C$28)/SUMIFS('إدخال المشتريات'!$D:$D,'إدخال المشتريات'!$C:$C,المنتجات!$C$28),0)) | F28: =IF(المنتجات!$C$28="","",SUMIFS('إدخال المبيعات'!$D:$D,'إدخال المبيعات'!$C:$C,المنتجات!$C$28,'إدخال المبيعات'!$B:$B,">="&'لوحة القيادة'!$C$4,'إدخال المبيعات'!$B:$B,"<="&'لوحة القيادة'!$E$4)) | G28: =IF(المنتجات!$C$28="","",SUMIFS('إدخال المبيعات'!$F:$F,'إدخال المبيعات'!$C:$C,المنتجات!$C$28,'إدخال المبيعات'!$B:$B,">="&'لوحة القيادة'!$C$4,'إدخال المبيعات'!$B:$B,"<="&'لوحة القيادة'!$E$4)) | H28: =IF(المنتجات!$C$28="","",E28*F28) | I28: =IF(المنتجات!$C$28="","",G28-H28) | J28: =IF(OR(المنتجات!$C$28="",G28=0),"",I28/G28) | K28: =IF(المنتجات!$C$28="","",SUMIFS('إدخال المشتريات'!$D:$D,'إدخال المشتريات'!$C:$C,المنتجات!$C$28)-SUMIFS('إدخال المبيعات'!$D:$D,'إدخال المبيعات'!$C:$C,المنتجات!$C$28)) | L28: =IF(المنتجات!$C$28="","",IF(K28<=المنتجات!$E$28,"⚠ أعد الطلب","جيد")) | M28: =IF(OR(المنتجات!$C$28="",I28=""),"",RANK(I28,$I$5:$I$34))
B29: =المنتجات!$C$29 -> 0 | C29: =IF(المنتجات!$C$29="","",SUMIFS('إدخال المشتريات'!$D:$D,'إدخال المشتريات'!$C:$C,المنتجات!$C$29,'إدخال المشتريات'!$B:$B,">="&'لوحة القيادة'!$C$4,'إدخال المشتريات'!$B:$B,"<="&'لوحة القيادة'!$E$4)) | D29: =IF(المنتجات!$C$29="","",SUMIFS('إدخال المشتريات'!$F:$F,'إدخال المشتريات'!$C:$C,المنتجات!$C$29,'إدخال المشتريات'!$B:$B,">="&'لوحة القيادة'!$C$4,'إدخال المشتريات'!$B:$B,"<="&'لوحة القيادة'!$E$4)) | E29: =IF(المنتجات!$C$29="","",IFERROR(SUMIFS('إدخال المشتريات'!$F:$F,'إدخال المشتريات'!$C:$C,المنتجات!$C$29)/SUMIFS('إدخال المشتريات'!$D:$D,'إدخال المشتريات'!$C:$C,المنتجات!$C$29),0)) | F29: =IF(المنتجات!$C$29="","",SUMIFS('إدخال المبيعات'!$D:$D,'إدخال المبيعات'!$C:$C,المنتجات!$C$29,'إدخال المبيعات'!$B:$B,">="&'لوحة القيادة'!$C$4,'إدخال المبيعات'!$B:$B,"<="&'لوحة القيادة'!$E$4)) | G29: =IF(المنتجات!$C$29="","",SUMIFS('إدخال المبيعات'!$F:$F,'إدخال المبيعات'!$C:$C,المنتجات!$C$29,'إدخال المبيعات'!$B:$B,">="&'لوحة القيادة'!$C$4,'إدخال المبيعات'!$B:$B,"<="&'لوحة القيادة'!$E$4)) | H29: =IF(المنتجات!$C$29="","",E29*F29) | I29: =IF(المنتجات!$C$29="","",G29-H29) | J29: =IF(OR(المنتجات!$C$29="",G29=0),"",I29/G29) | K29: =IF(المنتجات!$C$29="","",SUMIFS('إدخال المشتريات'!$D:$D,'إدخال المشتريات'!$C:$C,المنتجات!$C$29)-SUMIFS('إدخال المبيعات'!$D:$D,'إدخال المبيعات'!$C:$C,المنتجات!$C$29)) | L29: =IF(المنتجات!$C$29="","",IF(K29<=المنتجات!$E$29,"⚠ أعد الطلب","جيد")) | M29: =IF(OR(المنتجات!$C$29="",I29=""),"",RANK(I29,$I$5:$I$34))
B30: =المنتجات!$C$30 -> 0 | C30: =IF(المنتجات!$C$30="","",SUMIFS('إدخال المشتريات'!$D:$D,'إدخال المشتريات'!$C:$C,المنتجات!$C$30,'إدخال المشتريات'!$B:$B,">="&'لوحة القيادة'!$C$4,'إدخال المشتريات'!$B:$B,"<="&'لوحة القيادة'!$E$4)) | D30: =IF(المنتجات!$C$30="","",SUMIFS('إدخال المشتريات'!$F:$F,'إدخال المشتريات'!$C:$C,المنتجات!$C$30,'إدخال المشتريات'!$B:$B,">="&'لوحة القيادة'!$C$4,'إدخال المشتريات'!$B:$B,"<="&'لوحة القيادة'!$E$4)) | E30: =IF(المنتجات!$C$30="","",IFERROR(SUMIFS('إدخال المشتريات'!$F:$F,'إدخال المشتريات'!$C:$C,المنتجات!$C$30)/SUMIFS('إدخال المشتريات'!$D:$D,'إدخال المشتريات'!$C:$C,المنتجات!$C$30),0)) | F30: =IF(المنتجات!$C$30="","",SUMIFS('إدخال المبيعات'!$D:$D,'إدخال المبيعات'!$C:$C,المنتجات!$C$30,'إدخال المبيعات'!$B:$B,">="&'لوحة القيادة'!$C$4,'إدخال المبيعات'!$B:$B,"<="&'لوحة القيادة'!$E$4)) | G30: =IF(المنتجات!$C$30="","",SUMIFS('إدخال المبيعات'!$F:$F,'إدخال المبيعات'!$C:$C,المنتجات!$C$30,'إدخال المبيعات'!$B:$B,">="&'لوحة القيادة'!$C$4,'إدخال المبيعات'!$B:$B,"<="&'لوحة القيادة'!$E$4)) | H30: =IF(المنتجات!$C$30="","",E30*F30) | I30: =IF(المنتجات!$C$30="","",G30-H30) | J30: =IF(OR(المنتجات!$C$30="",G30=0),"",I30/G30) | K30: =IF(المنتجات!$C$30="","",SUMIFS('إدخال المشتريات'!$D:$D,'إدخال المشتريات'!$C:$C,المنتجات!$C$30)-SUMIFS('إدخال المبيعات'!$D:$D,'إدخال المبيعات'!$C:$C,المنتجات!$C$30)) | L30: =IF(المنتجات!$C$30="","",IF(K30<=المنتجات!$E$30,"⚠ أعد الطلب","جيد")) | M30: =IF(OR(المنتجات!$C$30="",I30=""),"",RANK(I30,$I$5:$I$34))
B31: =المنتجات!$C$31 -> 0 | C31: =IF(المنتجات!$C$31="","",SUMIFS('إدخال المشتريات'!$D:$D,'إدخال المشتريات'!$C:$C,المنتجات!$C$31,'إدخال المشتريات'!$B:$B,">="&'لوحة القيادة'!$C$4,'إدخال المشتريات'!$B:$B,"<="&'لوحة القيادة'!$E$4)) | D31: =IF(المنتجات!$C$31="","",SUMIFS('إدخال المشتريات'!$F:$F,'إدخال المشتريات'!$C:$C,المنتجات!$C$31,'إدخال المشتريات'!$B:$B,">="&'لوحة القيادة'!$C$4,'إدخال المشتريات'!$B:$B,"<="&'لوحة القيادة'!$E$4)) | E31: =IF(المنتجات!$C$31="","",IFERROR(SUMIFS('إدخال المشتريات'!$F:$F,'إدخال المشتريات'!$C:$C,المنتجات!$C$31)/SUMIFS('إدخال المشتريات'!$D:$D,'إدخال المشتريات'!$C:$C,المنتجات!$C$31),0)) | F31: =IF(المنتجات!$C$31="","",SUMIFS('إدخال المبيعات'!$D:$D,'إدخال المبيعات'!$C:$C,المنتجات!$C$31,'إدخال المبيعات'!$B:$B,">="&'لوحة القيادة'!$C$4,'إدخال المبيعات'!$B:$B,"<="&'لوحة القيادة'!$E$4)) | G31: =IF(المنتجات!$C$31="","",SUMIFS('إدخال المبيعات'!$F:$F,'إدخال المبيعات'!$C:$C,المنتجات!$C$31,'إدخال المبيعات'!$B:$B,">="&'لوحة القيادة'!$C$4,'إدخال المبيعات'!$B:$B,"<="&'لوحة القيادة'!$E$4)) | H31: =IF(المنتجات!$C$31="","",E31*F31) | I31: =IF(المنتجات!$C$31="","",G31-H31) | J31: =IF(OR(المنتجات!$C$31="",G31=0),"",I31/G31) | K31: =IF(المنتجات!$C$31="","",SUMIFS('إدخال المشتريات'!$D:$D,'إدخال المشتريات'!$C:$C,المنتجات!$C$31)-SUMIFS('إدخال المبيعات'!$D:$D,'إدخال المبيعات'!$C:$C,المنتجات!$C$31)) | L31: =IF(المنتجات!$C$31="","",IF(K31<=المنتجات!$E$31,"⚠ أعد الطلب","جيد")) | M31: =IF(OR(المنتجات!$C$31="",I31=""),"",RANK(I31,$I$5:$I$34))
B32: =المنتجات!$C$32 -> 0 | C32: =IF(المنتجات!$C$32="","",SUMIFS('إدخال المشتريات'!$D:$D,'إدخال المشتريات'!$C:$C,المنتجات!$C$32,'إدخال المشتريات'!$B:$B,">="&'لوحة القيادة'!$C$4,'إدخال المشتريات'!$B:$B,"<="&'لوحة القيادة'!$E$4)) | D32: =IF(المنتجات!$C$32="","",SUMIFS('إدخال المشتريات'!$F:$F,'إدخال المشتريات'!$C:$C,المنتجات!$C$32,'إدخال المشتريات'!$B:$B,">="&'لوحة القيادة'!$C$4,'إدخال المشتريات'!$B:$B,"<="&'لوحة القيادة'!$E$4)) | E32: =IF(المنتجات!$C$32="","",IFERROR(SUMIFS('إدخال المشتريات'!$F:$F,'إدخال المشتريات'!$C:$C,المنتجات!$C$32)/SUMIFS('إدخال المشتريات'!$D:$D,'إدخال المشتريات'!$C:$C,المنتجات!$C$32),0)) | F32: =IF(المنتجات!$C$32="","",SUMIFS('إدخال المبيعات'!$D:$D,'إدخال المبيعات'!$C:$C,المنتجات!$C$32,'إدخال المبيعات'!$B:$B,">="&'لوحة القيادة'!$C$4,'إدخال المبيعات'!$B:$B,"<="&'لوحة القيادة'!$E$4)) | G32: =IF(المنتجات!$C$32="","",SUMIFS('إدخال المبيعات'!$F:$F,'إدخال المبيعات'!$C:$C,المنتجات!$C$32,'إدخال المبيعات'!$B:$B,">="&'لوحة القيادة'!$C$4,'إدخال المبيعات'!$B:$B,"<="&'لوحة القيادة'!$E$4)) | H32: =IF(المنتجات!$C$32="","",E32*F32) | I32: =IF(المنتجات!$C$32="","",G32-H32) | J32: =IF(OR(المنتجات!$C$32="",G32=0),"",I32/G32) | K32: =IF(المنتجات!$C$32="","",SUMIFS('إدخال المشتريات'!$D:$D,'إدخال المشتريات'!$C:$C,المنتجات!$C$32)-SUMIFS('إدخال المبيعات'!$D:$D,'إدخال المبيعات'!$C:$C,المنتجات!$C$32)) | L32: =IF(المنتجات!$C$32="","",IF(K32<=المنتجات!$E$32,"⚠ أعد الطلب","جيد")) | M32: =IF(OR(المنتجات!$C$32="",I32=""),"",RANK(I32,$I$5:$I$34))
B33: =المنتجات!$C$33 -> 0 | C33: =IF(المنتجات!$C$33="","",SUMIFS('إدخال المشتريات'!$D:$D,'إدخال المشتريات'!$C:$C,المنتجات!$C$33,'إدخال المشتريات'!$B:$B,">="&'لوحة القيادة'!$C$4,'إدخال المشتريات'!$B:$B,"<="&'لوحة القيادة'!$E$4)) | D33: =IF(المنتجات!$C$33="","",SUMIFS('إدخال المشتريات'!$F:$F,'إدخال المشتريات'!$C:$C,المنتجات!$C$33,'إدخال المشتريات'!$B:$B,">="&'لوحة القيادة'!$C$4,'إدخال المشتريات'!$B:$B,"<="&'لوحة القيادة'!$E$4)) | E33: =IF(المنتجات!$C$33="","",IFERROR(SUMIFS('إدخال المشتريات'!$F:$F,'إدخال المشتريات'!$C:$C,المنتجات!$C$33)/SUMIFS('إدخال المشتريات'!$D:$D,'إدخال المشتريات'!$C:$C,المنتجات!$C$33),0)) | F33: =IF(المنتجات!$C$33="","",SUMIFS('إدخال المبيعات'!$D:$D,'إدخال المبيعات'!$C:$C,المنتجات!$C$33,'إدخال المبيعات'!$B:$B,">="&'لوحة القيادة'!$C$4,'إدخال المبيعات'!$B:$B,"<="&'لوحة القيادة'!$E$4)) | G33: =IF(المنتجات!$C$33="","",SUMIFS('إدخال المبيعات'!$F:$F,'إدخال المبيعات'!$C:$C,المنتجات!$C$33,'إدخال المبيعات'!$B:$B,">="&'لوحة القيادة'!$C$4,'إدخال المبيعات'!$B:$B,"<="&'لوحة القيادة'!$E$4)) | H33: =IF(المنتجات!$C$33="","",E33*F33) | I33: =IF(المنتجات!$C$33="","",G33-H33) | J33: =IF(OR(المنتجات!$C$33="",G33=0),"",I33/G33) | K33: =IF(المنتجات!$C$33="","",SUMIFS('إدخال المشتريات'!$D:$D,'إدخال المشتريات'!$C:$C,المنتجات!$C$33)-SUMIFS('إدخال المبيعات'!$D:$D,'إدخال المبيعات'!$C:$C,المنتجات!$C$33)) | L33: =IF(المنتجات!$C$33="","",IF(K33<=المنتجات!$E$33,"⚠ أعد الطلب","جيد")) | M33: =IF(OR(المنتجات!$C$33="",I33=""),"",RANK(I33,$I$5:$I$34))
B34: =المنتجات!$C$34 -> 0 | C34: =IF(المنتجات!$C$34="","",SUMIFS('إدخال المشتريات'!$D:$D,'إدخال المشتريات'!$C:$C,المنتجات!$C$34,'إدخال المشتريات'!$B:$B,">="&'لوحة القيادة'!$C$4,'إدخال المشتريات'!$B:$B,"<="&'لوحة القيادة'!$E$4)) | D34: =IF(المنتجات!$C$34="","",SUMIFS('إدخال المشتريات'!$F:$F,'إدخال المشتريات'!$C:$C,المنتجات!$C$34,'إدخال المشتريات'!$B:$B,">="&'لوحة القيادة'!$C$4,'إدخال المشتريات'!$B:$B,"<="&'لوحة القيادة'!$E$4)) | E34: =IF(المنتجات!$C$34="","",IFERROR(SUMIFS('إدخال المشتريات'!$F:$F,'إدخال المشتريات'!$C:$C,المنتجات!$C$34)/SUMIFS('إدخال المشتريات'!$D:$D,'إدخال المشتريات'!$C:$C,المنتجات!$C$34),0)) | F34: =IF(المنتجات!$C$34="","",SUMIFS('إدخال المبيعات'!$D:$D,'إدخال المبيعات'!$C:$C,المنتجات!$C$34,'إدخال المبيعات'!$B:$B,">="&'لوحة القيادة'!$C$4,'إدخال المبيعات'!$B:$B,"<="&'لوحة القيادة'!$E$4)) | G34: =IF(المنتجات!$C$34="","",SUMIFS('إدخال المبيعات'!$F:$F,'إدخال المبيعات'!$C:$C,المنتجات!$C$34,'إدخال المبيعات'!$B:$B,">="&'لوحة القيادة'!$C$4,'إدخال المبيعات'!$B:$B,"<="&'لوحة القيادة'!$E$4)) | H34: =IF(المنتجات!$C$34="","",E34*F34) | I34: =IF(المنتجات!$C$34="","",G34-H34) | J34: =IF(OR(المنتجات!$C$34="",G34=0),"",I34/G34) | K34: =IF(المنتجات!$C$34="","",SUMIFS('إدخال المشتريات'!$D:$D,'إدخال المشتريات'!$C:$C,المنتجات!$C$34)-SUMIFS('إدخال المبيعات'!$D:$D,'إدخال المبيعات'!$C:$C,المنتجات!$C$34)) | L34: =IF(المنتجات!$C$34="","",IF(K34<=المنتجات!$E$34,"⚠ أعد الطلب","جيد")) | M34: =IF(OR(المنتجات!$C$34="",I34=""),"",RANK(I34,$I$5:$I$34))
B35: الإجمالي | C35: =SUM(C5:C34) -> 7283 | D35: =SUM(D5:D34) -> 3185390 | E35: - | F35: =SUM(F5:F34) -> 5149 | G35: =SUM(G5:G34) -> 2574553.3 | H35: =SUM(H5:H34) -> 2223270.3 | I35: =SUM(I5:I34) -> 351283.02 | J35: =IFERROR(I35/G35,0) -> 0.13644426 | K35: =SUM(K5:K34) -> 2134 | L35: - | M35: -
B37: تكلفة البضاعة المباعة تُحسب بمتوسط سعر الشراء المرجّح لكل مشتريات المنتج (كل الفترات)، بينما المخزون الحالي دائماً يُحسب على أساس كل الفترات بغضّ النظر عن فلتر التاريخ أعلاه — لأن المخزون حالة لحظية وليست حركة ضمن فترة.

Sheet التنبؤ وإعادة الطلب
B1: التنبؤ بالمبيعات واقتراح إعادة الطلب
B2: التنبؤ مبني على معدل البيع اليومي الفعلي لكل منتج منذ أول عملية بيع له
B4: أفق التنبؤ (عدد الأيام القادمة): | E4: 30
B6: المنتج | C6: أول تاريخ بيع | D6: آخر تاريخ بيع | E6: عدد أيام النشاط | F6: معدل المبيعات اليومي (كمية) | G6: معدل المبيعات اليومي (قيمة) | H6: الكمية المتوقعة خلال الأفق | I6: القيمة المتوقعة خلال الأفق | J6: الربح المتوقع خلال الأفق | K6: المخزون الحالي | L6: الكمية المقترح شراؤها
B7: =المنتجات!$C$5 -> عصير جومانة 2ل | C7: =IF(المنتجات!$C$5="","",IF(المنتجات!$D$5<>"",المنتجات!$D$5,IFERROR(_xlfn.MINIFS('إدخال المبيعات'!$B:$B,'إدخال المبيعات'!$C:$C,المنتجات!$C$5),""))) -> 46198 | D7: =IF(المنتجات!$C$5="","",IFERROR(_xlfn.MAXIFS('إدخال المبيعات'!$B:$B,'إدخال المبيعات'!$C:$C,المنتجات!$C$5),"")) -> 46236 | E7: =IF(OR(C7="",D7=""),"",MAX(D7-C7+1,1)) -> 39 | F7: =IF(E7="","",SUMIFS('إدخال المبيعات'!$D:$D,'إدخال المبيعات'!$C:$C,المنتجات!$C$5)/E7) -> 30.820513 | G7: =IF(E7="","",SUMIFS('إدخال المبيعات'!$F:$F,'إدخال المبيعات'!$C:$C,المنتجات!$C$5)/E7) -> 13869.16 | H7: =IF(F7="","",F7*$E$4) -> 924.61538 | I7: =IF(G7="","",G7*$E$4) -> 416074.8 | J7: =IF(OR(H7="",F7="",F7=0),"",H7*(IFERROR(G7/F7,0)-IFERROR('تقرير المنتجات'!$E$5,0))) -> 73967.108 | K7: =IF(المنتجات!$C$5="","",'تقرير المنتجات'!$K$5) -> 638 | L7: =IF(OR(H7="",K7=""),"",MAX(H7-K7,0)) -> 286.61538
B8: =المنتجات!$C$6 -> عصير كين دور 1.25ل | C8: =IF(المنتجات!$C$6="","",IF(المنتجات!$D$6<>"",المنتجات!$D$6,IFERROR(_xlfn.MINIFS('إدخال المبيعات'!$B:$B,'إدخال المبيعات'!$C:$C,المنتجات!$C$6),""))) -> 46198 | D8: =IF(المنتجات!$C$6="","",IFERROR(_xlfn.MAXIFS('إدخال المبيعات'!$B:$B,'إدخال المبيعات'!$C:$C,المنتجات!$C$6),"")) -> 46236 | E8: =IF(OR(C8="",D8=""),"",MAX(D8-C8+1,1)) -> 39 | F8: =IF(E8="","",SUMIFS('إدخال المبيعات'!$D:$D,'إدخال المبيعات'!$C:$C,المنتجات!$C$6)/E8) -> 24.538462 | G8: =IF(E8="","",SUMIFS('إدخال المبيعات'!$F:$F,'إدخال المبيعات'!$C:$C,المنتجات!$C$6)/E8) -> 9324.5238 | H8: =IF(F8="","",F8*$E$4) -> 736.15385 | I8: =IF(G8="","",G8*$E$4) -> 279735.72 | J8: =IF(OR(H8="",F8="",F8=0),"",H8*(IFERROR(G8/F8,0)-IFERROR('تقرير المنتجات'!$E$6,0))) -> 55208.792 | K8: =IF(المنتجات!$C$6="","",'تقرير المنتجات'!$K$6) -> -19 | L8: =IF(OR(H8="",K8=""),"",MAX(H8-K8,0)) -> 755.15385
B9: =المنتجات!$C$7 -> عصير مدى 33سل | C9: =IF(المنتجات!$C$7="","",IF(المنتجات!$D$7<>"",المنتجات!$D$7,IFERROR(_xlfn.MINIFS('إدخال المبيعات'!$B:$B,'إدخال المبيعات'!$C:$C,المنتجات!$C$7),""))) -> 46198 | D9: =IF(المنتجات!$C$7="","",IFERROR(_xlfn.MAXIFS('إدخال المبيعات'!$B:$B,'إدخال المبيعات'!$C:$C,المنتجات!$C$7),"")) -> 46236 | E9: =IF(OR(C9="",D9=""),"",MAX(D9-C9+1,1)) -> 39 | F9: =IF(E9="","",SUMIFS('إدخال المبيعات'!$D:$D,'إدخال المبيعات'!$C:$C,المنتجات!$C$7)/E9) -> 16.74359 | G9: =IF(E9="","",SUMIFS('إدخال المبيعات'!$F:$F,'إدخال المبيعات'!$C:$C,المنتجات!$C$7)/E9) -> 6697.4282 | H9: =IF(F9="","",F9*$E$4) -> 502.30769 | I9: =IF(G9="","",G9*$E$4) -> 200922.85 | J9: =IF(OR(H9="",F9="",F9=0),"",H9*(IFERROR(G9/F9,0)-IFERROR('تقرير المنتجات'!$E$7,0))) -> 40184.385 | K9: =IF(المنتجات!$C$7="","",'تقرير المنتجات'!$K$7) -> 697 | L9: =IF(OR(H9="",K9=""),"",MAX(H9-K9,0)) -> 0
B10: =المنتجات!$C$8 -> عصير اكسترا 2ل | C10: =IF(المنتجات!$C$8="","",IF(المنتجات!$D$8<>"",المنتجات!$D$8,IFERROR(_xlfn.MINIFS('إدخال المبيعات'!$B:$B,'إدخال المبيعات'!$C:$C,المنتجات!$C$8),""))) -> 46198 | D10: =IF(المنتجات!$C$8="","",IFERROR(_xlfn.MAXIFS('إدخال المبيعات'!$B:$B,'إدخال المبيعات'!$C:$C,المنتجات!$C$8),"")) -> 46231 | E10: =IF(OR(C10="",D10=""),"",MAX(D10-C10+1,1)) -> 34 | F10: =IF(E10="","",SUMIFS('إدخال المبيعات'!$D:$D,'إدخال المبيعات'!$C:$C,المنتجات!$C$8)/E10) -> 9.2941176 | G10: =IF(E10="","",SUMIFS('إدخال المبيعات'!$F:$F,'إدخال المبيعات'!$C:$C,المنتجات!$C$8)/E10) -> 5558.2541 | H10: =IF(F10="","",F10*$E$4) -> 278.82353 | I10: =IF(G10="","",G10*$E$4) -> 166747.62 | J10: =IF(OR(H10="",F10="",F10=0),"",H10*(IFERROR(G10/F10,0)-IFERROR('تقرير المنتجات'!$E$8,0))) -> 27335.859 | K10: =IF(المنتجات!$C$8="","",'تقرير المنتجات'!$K$8) -> 4 | L10: =IF(OR(H10="",K10=""),"",MAX(H10-K10,0)) -> 274.82353
B11: =المنتجات!$C$9 -> عصير مدى 1.5ل | C11: =IF(المنتجات!$C$9="","",IF(المنتجات!$D$9<>"",المنتجات!$D$9,IFERROR(_xlfn.MINIFS('إدخال المبيعات'!$B:$B,'إدخال المبيعات'!$C:$C,المنتجات!$C$9),""))) -> 46198 | D11: =IF(المنتجات!$C$9="","",IFERROR(_xlfn.MAXIFS('إدخال المبيعات'!$B:$B,'إدخال المبيعات'!$C:$C,المنتجات!$C$9),"")) -> 46236 | E11: =IF(OR(C11="",D11=""),"",MAX(D11-C11+1,1)) -> 39 | F11: =IF(E11="","",SUMIFS('إدخال المبيعات'!$D:$D,'إدخال المبيعات'!$C:$C,المنتجات!$C$9)/E11) -> 8.1282051 | G11: =IF(E11="","",SUMIFS('إدخال المبيعات'!$F:$F,'إدخال المبيعات'!$C:$C,المنتجات!$C$9)/E11) -> 4876.9056 | H11: =IF(F11="","",F11*$E$4) -> 243.84615 | I11: =IF(G11="","",G11*$E$4) -> 146307.17 | J11: =IF(OR(H11="",F11="",F11=0),"",H11*(IFERROR(G11/F11,0)-IFERROR('تقرير المنتجات'!$E$9,0))) -> 24384.092 | K11: =IF(المنتجات!$C$9="","",'تقرير المنتجات'!$K$9) -> 83 | L11: =IF(OR(H11="",K11=""),"",MAX(H11-K11,0)) -> 160.84615
